Workbook

Sheet Relação de NF's
A1: Area | B1: Documento | C1: Pacote | D1: Categoria | E1: Razão Social | F1: Tipo | G1: CNPJ/CPF | H1: Filial | I1: Valor Doc | J1: Emissão | K1: Referência | L1: Munícipio | M1: UF | N1: CFOP | O1: Atualizado Por | S1: Janeiro | T1: Fevereiro | U1: Março | V1: Abril | W1: Maio | X1: Junho | Y1: Julho | Z1: Agosto | AA1: Setembro | AB1: Outubro | AC1: Novembro | AD1: Dezembro
A2: =VLOOKUP($E2,Fornecedores!$A:$C,3,0) -> Frota | B2: AGMTZ-2883681 | C2: =IFERROR(VLOOKUP($E2,Fornecedores!$A:$E,4,0),"") -> OPE Merchandising | D2: =IFERROR(VLOOKUP($E2,Fornecedores!$A:$E,5,0),"") -> Locação | E2: LOCALIZA FLEET S/A | F2: FT | G2: 02.286.479/0001-08 | H2: 87 | I2: 34.5 | J2: 46006 | K2: 46028 | L2: BELO HORIZONTE | M2: MG | N2: 1556 | O2: GABRIEL.ALBINO | Q2: =SUM(R2:AD2)-I2 -> 0 | S2: =SUMIFS('Doc''s Pagos | Rodopar 108'!$J:$J,'Doc''s Pagos | Rodopar 108'!$A:$A,$B2&$E2&$F2&$J2,'Doc''s Pagos | Rodopar 108'!$B:$B,S$1)+SUMIFS('Doc Há Pagar | Rodopar 1015'!$J:$J,'Doc Há Pagar | Rodopar 1015'!$A:$A,$B2&$E2&$F2,'Doc Há Pagar | Rodopar 1015'!$B:$B,S$1) -> 34.5 | T2: =SUMIFS('Doc''s Pagos | Rodopar 108'!$J:$J,'Doc''s Pagos | Rodopar 108'!$A:$A,$B2&$E2&$F2&$J2,'Doc''s Pagos | Rodopar 108'!$B:$B,T$1)+SUMIFS('Doc Há Pagar | Rodopar 1015'!$J:$J,'Doc Há Pagar | Rodopar 1015'!$A:$A,$B2&$E2&$F2,'Doc Há Pagar | Rodopar 1015'!$B:$B,T$1) -> 0 | U2: =SUMIFS('Doc''s Pagos | Rodopar 108'!$J:$J,'Doc''s Pagos | Rodopar 108'!$A:$A,$B2&$E2&$F2&$J2,'Doc''s Pagos | Rodopar 108'!$B:$B,U$1)+SUMIFS('Doc Há Pagar | Rodopar 1015'!$J:$J,'Doc Há Pagar | Rodopar 1015'!$A:$A,$B2&$E2&$F2,'Doc Há Pagar | Rodopar 1015'!$B:$B,U$1) -> 0 | V2: =SUMIFS('Doc''s Pagos | Rodopar 108'!$J:$J,'Doc''s Pagos | Rodopar 108'!$A:$A,$B2&$E2&$F2&$J2,'Doc''s Pagos | Rodopar 108'!$B:$B,V$1)+SUMIFS('Doc Há Pagar | Rodopar 1015'!$J:$J,'Doc Há Pagar | Rodopar 1015'!$A:$A,$B2&$E2&$F2,'Doc Há Pagar | Rodopar 1015'!$B:$B,V$1) -> 0 | W2: =SUMIFS('Doc''s Pagos | Rodopar 108'!$J:$J,'Doc''s Pagos | Rodopar 108'!$A:$A,$B2&$E2&$F2&$J2,'Doc''s Pagos | Rodopar 108'!$B:$B,W$1)+SUMIFS('Doc Há Pagar | Rodopar 1015'!$J:$J,'Doc Há Pagar | Rodopar 1015'!$A:$A,$B2&$E2&$F2,'Doc Há Pagar | Rodopar 1015'!$B:$B,W$1) -> 0 | X2: =SUMIFS('Doc''s Pagos | Rodopar 108'!$J:$J,'Doc''s Pagos | Rodopar 108'!$A:$A,$B2&$E2&$F2&$J2,'Doc''s Pagos | Rodopar 108'!$B:$B,X$1)+SUMIFS('Doc Há Pagar | Rodopar 1015'!$J:$J,'Doc Há Pagar | Rodopar 1015'!$A:$A,$B2&$E2&$F2,'Doc Há Pagar | Rodopar 1015'!$B:$B,X$1) -> 0 | Y2: =SUMIFS('Doc''s Pagos | Rodopar 108'!$J:$J,'Doc''s Pagos | Rodopar 108'!$A:$A,$B2&$E2&$F2&$J2,'Doc''s Pagos | Rodopar 108'!$B:$B,Y$1)+SUMIFS('Doc Há Pagar | Rodopar 1015'!$J:$J,'Doc Há Pagar | Rodopar 1015'!$A:$A,$B2&$E2&$F2,'Doc Há Pagar | Rodopar 1015'!$B:$B,Y$1) -> 0 | Z2: =SUMIFS('Doc''s Pagos | Rodopar 108'!$J:$J,'Doc''s Pagos | Rodopar 108'!$A:$A,$B2&$E2&$F2&$J2,'Doc''s Pagos | Rodopar 108'!$B:$B,Z$1)+SUMIFS('Doc Há Pagar | Rodopar 1015'!$J:$J,'Doc Há Pagar | Rodopar 1015'!$A:$A,$B2&$E2&$F2,'Doc Há Pagar | Rodopar 1015'!$B:$B,Z$1) -> 0 | ... AD2: =SUMIFS('Doc''s Pagos | Rodopar 108'!$J:$J,'Doc''s Pagos | Rodopar 108'!$A:$A,$B2&$E2&$F2&$J2,'Doc''s Pagos | Rodopar 108'!$B:$B,AD$1)+SUMIFS('Doc Há Pagar | Rodopar 1015'!$J:$J,'Doc Há Pagar | Rodopar 1015'!$A:$A,$B2&$E2&$F2,'Doc Há Pagar | Rodopar 1015'!$B:$B,AD$1) -> 0
A3: =VLOOKUP($E3,Fornecedores!$A:$C,3,0) -> Frota | B3: 2631 | C3: =IFERROR(VLOOKUP($E3,Fornecedores!$A:$E,4,0),"") -> Manutenção | D3: =IFERROR(VLOOKUP($E3,Fornecedores!$A:$E,5,0),"") -> Frota Leve OPE | E3: MECANICA CRISTO REI LTDA | F3: NFE | G3: 71.299.614/0001-64 | H3: 87 | I3: 898 | J3: 46013 | K3: 46028 | L3: CONTAGEM | M3: MG | N3: 1556 | O3: GABRIEL.ALBINO | Q3: =SUM(R3:AD3)-I3 -> 0 | S3: =SUMIFS('Doc''s Pagos | Rodopar 108'!$J:$J,'Doc''s Pagos | Rodopar 108'!$A:$A,$B3&$E3&$F3&$J3,'Doc''s Pagos | Rodopar 108'!$B:$B,S$1)+SUMIFS('Doc Há Pagar | Rodopar 1015'!$J:$J,'Doc Há Pagar | Rodopar 1015'!$A:$A,$B3&$E3&$F3,'Doc Há Pagar | Rodopar 1015'!$B:$B,S$1) -> 898 | T3: =SUMIFS('Doc''s Pagos | Rodopar 108'!$J:$J,'Doc''s Pagos | Rodopar 108'!$A:$A,$B3&$E3&$F3&$J3,'Doc''s Pagos | Rodopar 108'!$B:$B,T$1)+SUMIFS('Doc Há Pagar | Rodopar 1015'!$J:$J,'Doc Há Pagar | Rodopar 1015'!$A:$A,$B3&$E3&$F3,'Doc Há Pagar | Rodopar 1015'!$B:$B,T$1) -> 0 | U3: =SUMIFS('Doc''s Pagos | Rodopar 108'!$J:$J,'Doc''s Pagos | Rodopar 108'!$A:$A,$B3&$E3&$F3&$J3,'Doc''s Pagos | Rodopar 108'!$B:$B,U$1)+SUMIFS('Doc Há Pagar | Rodopar 1015'!$J:$J,'Doc Há Pagar | Rodopar 1015'!$A:$A,$B3&$E3&$F3,'Doc Há Pagar | Rodopar 1015'!$B:$B,U$1) -> 0 | V3: =SUMIFS('Doc''s Pagos | Rodopar 108'!$J:$J,'Doc''s Pagos | Rodopar 108'!$A:$A,$B3&$E3&$F3&$J3,'Doc''s Pagos | Rodopar 108'!$B:$B,V$1)+SUMIFS('Doc Há Pagar | Rodopar 1015'!$J:$J,'Doc Há Pagar | Rodopar 1015'!$A:$A,$B3&$E3&$F3,'Doc Há Pagar | Rodopar 1015'!$B:$B,V$1) -> 0 | W3: =SUMIFS('Doc''s Pagos | Rodopar 108'!$J:$J,'Doc''s Pagos | Rodopar 108'!$A:$A,$B3&$E3&$F3&$J3,'Doc''s Pagos | Rodopar 108'!$B:$B,W$1)+SUMIFS('Doc Há Pagar | Rodopar 1015'!$J:$J,'Doc Há Pagar | Rodopar 1015'!$A:$A,$B3&$E3&$F3,'Doc Há Pagar | Rodopar 1015'!$B:$B,W$1) -> 0 | X3: =SUMIFS('Doc''s Pagos | Rodopar 108'!$J:$J,'Doc''s Pagos | Rodopar 108'!$A:$A,$B3&$E3&$F3&$J3,'Doc''s Pagos | Rodopar 108'!$B:$B,X$1)+SUMIFS('Doc Há Pagar | Rodopar 1015'!$J:$J,'Doc Há Pagar | Rodopar 1015'!$A:$A,$B3&$E3&$F3,'Doc Há Pagar | Rodopar 1015'!$B:$B,X$1) -> 0 | Y3: =SUMIFS('Doc''s Pagos | Rodopar 108'!$J:$J,'Doc''s Pagos | Rodopar 108'!$A:$A,$B3&$E3&$F3&$J3,'Doc''s Pagos | Rodopar 108'!$B:$B,Y$1)+SUMIFS('Doc Há Pagar | Rodopar 1015'!$J:$J,'Doc Há Pagar | Rodopar 1015'!$A:$A,$B3&$E3&$F3,'Doc Há Pagar | Rodopar 1015'!$B:$B,Y$1) -> 0 | Z3: =SUMIFS('Doc''s Pagos | Rodopar 108'!$J:$J,'Doc''s Pagos | Rodopar 108'!$A:$A,$B3&$E3&$F3&$J3,'Doc''s Pagos | Rodopar 108'!$B:$B,Z$1)+SUMIFS('Doc Há Pagar | Rodopar 1015'!$J:$J,'Doc Há Pagar | Rodopar 1015'!$A:$A,$B3&$E3&$F3,'Doc Há Pagar | Rodopar 1015'!$B:$B,Z$1) -> 0 | ... AD3: =SUMIFS('Doc''s Pagos | Rodopar 108'!$J:$J,'Doc''s Pagos | Rodopar 108'!$A:$A,$B3&$E3&$F3&$J3,'Doc''s Pagos | Rodopar 108'!$B:$B,AD$1)+SUMIFS('Doc Há Pagar | Rodopar 1015'!$J:$J,'Doc Há Pagar | Rodopar 1015'!$A:$A,$B3&$E3&$F3,'Doc Há Pagar | Rodopar 1015'!$B:$B,AD$1) -> 0
A4: =VLOOKUP($E4,Fornecedores!$A:$C,3,0) -> Frota | B4: 2632 | C4: =IFERROR(VLOOKUP($E4,Fornecedores!$A:$E,4,0),"") -> Manutenção | D4: =IFERROR(VLOOKUP($E4,Fornecedores!$A:$E,5,0),"") -> Frota Leve OPE | E4: MECANICA CRISTO REI LTDA | F4: NFE | G4: 71.299.614/0001-64 | H4: 87 | I4: 1338 | J4: 46013 | K4: 46028 | L4: CONTAGEM | M4: MG | N4: 1556 | O4: GABRIEL.ALBINO | Q4: =SUM(R4:AD4)-I4 -> 0 | S4: =SUMIFS('Doc''s Pagos | Rodopar 108'!$J:$J,'Doc''s Pagos | Rodopar 108'!$A:$A,$B4&$E4&$F4&$J4,'Doc''s Pagos | Rodopar 108'!$B:$B,S$1)+SUMIFS('Doc Há Pagar | Rodopar 1015'!$J:$J,'Doc Há Pagar | Rodopar 1015'!$A:$A,$B4&$E4&$F4,'Doc Há Pagar | Rodopar 1015'!$B:$B,S$1) -> 1338 | T4: =SUMIFS('Doc''s Pagos | Rodopar 108'!$J:$J,'Doc''s Pagos | Rodopar 108'!$A:$A,$B4&$E4&$F4&$J4,'Doc''s Pagos | Rodopar 108'!$B:$B,T$1)+SUMIFS('Doc Há Pagar | Rodopar 1015'!$J:$J,'Doc Há Pagar | Rodopar 1015'!$A:$A,$B4&$E4&$F4,'Doc Há Pagar | Rodopar 1015'!$B:$B,T$1) -> 0 | U4: =SUMIFS('Doc''s Pagos | Rodopar 108'!$J:$J,'Doc''s Pagos | Rodopar 108'!$A:$A,$B4&$E4&$F4&$J4,'Doc''s Pagos | Rodopar 108'!$B:$B,U$1)+SUMIFS('Doc Há Pagar | Rodopar 1015'!$J:$J,'Doc Há Pagar | Rodopar 1015'!$A:$A,$B4&$E4&$F4,'Doc Há Pagar | Rodopar 1015'!$B:$B,U$1) -> 0 | V4: =SUMIFS('Doc''s Pagos | Rodopar 108'!$J:$J,'Doc''s Pagos | Rodopar 108'!$A:$A,$B4&$E4&$F4&$J4,'Doc''s Pagos | Rodopar 108'!$B:$B,V$1)+SUMIFS('Doc Há Pagar | Rodopar 1015'!$J:$J,'Doc Há Pagar | Rodopar 1015'!$A:$A,$B4&$E4&$F4,'Doc Há Pagar | Rodopar 1015'!$B:$B,V$1) -> 0 | W4: =SUMIFS('Doc''s Pagos | Rodopar 108'!$J:$J,'Doc''s Pagos | Rodopar 108'!$A:$A,$B4&$E4&$F4&$J4,'Doc''s Pagos | Rodopar 108'!$B:$B,W$1)+SUMIFS('Doc Há Pagar | Rodopar 1015'!$J:$J,'Doc Há Pagar | Rodopar 1015'!$A:$A,$B4&$E4&$F4,'Doc Há Pagar | Rodopar 1015'!$B:$B,W$1) -> 0 | X4: =SUMIFS('Doc''s Pagos | Rodopar 108'!$J:$J,'Doc''s Pagos | Rodopar 108'!$A:$A,$B4&$E4&$F4&$J4,'Doc''s Pagos | Rodopar 108'!$B:$B,X$1)+SUMIFS('Doc Há Pagar | Rodopar 1015'!$J:$J,'Doc Há Pagar | Rodopar 1015'!$A:$A,$B4&$E4&$F4,'Doc Há Pagar | Rodopar 1015'!$B:$B,X$1) -> 0 | Y4: =SUMIFS('Doc''s Pagos | Rodopar 108'!$J:$J,'Doc''s Pagos | Rodopar 108'!$A:$A,$B4&$E4&$F4&$J4,'Doc''s Pagos | Rodopar 108'!$B:$B,Y$1)+SUMIFS('Doc Há Pagar | Rodopar 1015'!$J:$J,'Doc Há Pagar | Rodopar 1015'!$A:$A,$B4&$E4&$F4,'Doc Há Pagar | Rodopar 1015'!$B:$B,Y$1) -> 0 | Z4: =SUMIFS('Doc''s Pagos | Rodopar 108'!$J:$J,'Doc''s Pagos | Rodopar 108'!$A:$A,$B4&$E4&$F4&$J4,'Doc''s Pagos | Rodopar 108'!$B:$B,Z$1)+SUMIFS('Doc Há Pagar | Rodopar 1015'!$J:$J,'Doc Há Pagar | Rodopar 1015'!$A:$A,$B4&$E4&$F4,'Doc Há Pagar | Rodopar 1015'!$B:$B,Z$1) -> 0 | ... AD4: =SUMIFS('Doc''s Pagos | Rodopar 108'!$J:$J,'Doc''s Pagos | Rodopar 108'!$A:$A,$B4&$E4&$F4&$J4,'Doc''s Pagos | Rodopar 108'!$B:$B,AD$1)+SUMIFS('Doc Há Pagar | Rodopar 1015'!$J:$J,'Doc Há Pagar | Rodopar 1015'!$A:$A,$B4&$E4&$F4,'Doc Há Pagar | Rodopar 1015'!$B:$B,AD$1) -> 0
A5: =VLOOKUP($E5,Fornecedores!$A:$C,3,0) -> Frota | B5: 3780 | C5: =IFERROR(VLOOKUP($E5,Fornecedores!$A:$E,4,0),"") -> Manutenção | D5: =IFERROR(VLOOKUP($E5,Fornecedores!$A:$E,5,0),"") -> Frota Leve OPE | E5: MECANICA CRISTO REI LTDA | F5: NSE | G5: 71.299.614/0001-64 | H5: 87 | I5: 490 | J5: 46013 | K5: 46027 | L5: CONTAGEM | M5: MG | N5: 1556 | O5: GABRIEL.ALBINO | Q5: =SUM(R5:AD5)-I5 -> 0 | S5: =SUMIFS('Doc''s Pagos | Rodopar 108'!$J:$J,'Doc''s Pagos | Rodopar 108'!$A:$A,$B5&$E5&$F5&$J5,'Doc''s Pagos | Rodopar 108'!$B:$B,S$1)+SUMIFS('Doc Há Pagar | Rodopar 1015'!$J:$J,'Doc Há Pagar | Rodopar 1015'!$A:$A,$B5&$E5&$F5,'Doc Há Pagar | Rodopar 1015'!$B:$B,S$1) -> 490 | T5: =SUMIFS('Doc''s Pagos | Rodopar 108'!$J:$J,'Doc''s Pagos | Rodopar 108'!$A:$A,$B5&$E5&$F5&$J5,'Doc''s Pagos | Rodopar 108'!$B:$B,T$1)+SUMIFS('Doc Há Pagar | Rodopar 1015'!$J:$J,'Doc Há Pagar | Rodopar 1015'!$A:$A,$B5&$E5&$F5,'Doc Há Pagar | Rodopar 1015'!$B:$B,T$1) -> 0 | U5: =SUMIFS('Doc''s Pagos | Rodopar 108'!$J:$J,'Doc''s Pagos | Rodopar 108'!$A:$A,$B5&$E5&$F5&$J5,'Doc''s Pagos | Rodopar 108'!$B:$B,U$1)+SUMIFS('Doc Há Pagar | Rodopar 1015'!$J:$J,'Doc Há Pagar | Rodopar 1015'!$A:$A,$B5&$E5&$F5,'Doc Há Pagar | Rodopar 1015'!$B:$B,U$1) -> 0 | V5: =SUMIFS('Doc''s Pagos | Rodopar 108'!$J:$J,'Doc''s Pagos | Rodopar 108'!$A:$A,$B5&$E5&$F5&$J5,'Doc''s Pagos | Rodopar 108'!$B:$B,V$1)+SUMIFS('Doc Há Pagar | Rodopar 1015'!$J:$J,'Doc Há Pagar | Rodopar 1015'!$A:$A,$B5&$E5&$F5,'Doc Há Pagar | Rodopar 1015'!$B:$B,V$1) -> 0 | W5: =SUMIFS('Doc''s Pagos | Rodopar 108'!$J:$J,'Doc''s Pagos | Rodopar 108'!$A:$A,$B5&$E5&$F5&$J5,'Doc''s Pagos | Rodopar 108'!$B:$B,W$1)+SUMIFS('Doc Há Pagar | Rodopar 1015'!$J:$J,'Doc Há Pagar | Rodopar 1015'!$A:$A,$B5&$E5&$F5,'Doc Há Pagar | Rodopar 1015'!$B:$B,W$1) -> 0 | X5: =SUMIFS('Doc''s Pagos | Rodopar 108'!$J:$J,'Doc''s Pagos | Rodopar 108'!$A:$A,$B5&$E5&$F5&$J5,'Doc''s Pagos | Rodopar 108'!$B:$B,X$1)+SUMIFS('Doc Há Pagar | Rodopar 1015'!$J:$J,'Doc Há Pagar | Rodopar 1015'!$A:$A,$B5&$E5&$F5,'Doc Há Pagar | Rodopar 1015'!$B:$B,X$1) -> 0 | Y5: =SUMIFS('Doc''s Pagos | Rodopar 108'!$J:$J,'Doc''s Pagos | Rodopar 108'!$A:$A,$B5&$E5&$F5&$J5,'Doc''s Pagos | Rodopar 108'!$B:$B,Y$1)+SUMIFS('Doc Há Pagar | Rodopar 1015'!$J:$J,'Doc Há Pagar | Rodopar 1015'!$A:$A,$B5&$E5&$F5,'Doc Há Pagar | Rodopar 1015'!$B:$B,Y$1) -> 0 | Z5: =SUMIFS('Doc''s Pagos | Rodopar 108'!$J:$J,'Doc''s Pagos | Rodopar 108'!$A:$A,$B5&$E5&$F5&$J5,'Doc''s Pagos | Rodopar 108'!$B:$B,Z$1)+SUMIFS('Doc Há Pagar | Rodopar 1015'!$J:$J,'Doc Há Pagar | Rodopar 1015'!$A:$A,$B5&$E5&$F5,'Doc Há Pagar | Rodopar 1015'!$B:$B,Z$1) -> 0 | ... AD5: =SUMIFS('Doc''s Pagos | Rodopar 108'!$J:$J,'Doc''s Pagos | Rodopar 108'!$A:$A,$B5&$E5&$F5&$J5,'Doc''s Pagos | Rodopar 108'!$B:$B,AD$1)+SUMIFS('Doc Há Pagar | Rodopar 1015'!$J:$J,'Doc Há Pagar | Rodopar 1015'!$A:$A,$B5&$E5&$F5,'Doc Há Pagar | Rodopar 1015'!$B:$B,AD$1) -> 0
A6: =VLOOKUP($E6,Fornecedores!$A:$C,3,0) -> Frota | B6: 3781 | C6: =IFERROR(VLOOKUP($E6,Fornecedores!$A:$E,4,0),"") -> Manutenção | D6: =IFERROR(VLOOKUP($E6,Fornecedores!$A:$E,5,0),"") -> Frota Leve OPE | E6: MECANICA CRISTO REI LTDA | F6: NSE | G6: 71.299.614/0001-64 | H6: 87 | I6: 430 | J6: 46013 | K6: 46027 | L6: CONTAGEM | M6: MG | N6: 1556 | O6: GABRIEL.ALBINO | Q6: =SUM(R6:AD6)-I6 -> 0 | S6: =SUMIFS('Doc''s Pagos | Rodopar 108'!$J:$J,'Doc''s Pagos | Rodopar 108'!$A:$A,$B6&$E6&$F6&$J6,'Doc''s Pagos | Rodopar 108'!$B:$B,S$1)+SUMIFS('Doc Há Pagar | Rodopar 1015'!$J:$J,'Doc Há Pagar | Rodopar 1015'!$A:$A,$B6&$E6&$F6,'Doc Há Pagar | Rodopar 1015'!$B:$B,S$1) -> 430 | T6: =SUMIFS('Doc''s Pagos | Rodopar 108'!$J:$J,'Doc''s Pagos | Rodopar 108'!$A:$A,$B6&$E6&$F6&$J6,'Doc''s Pagos | Rodopar 108'!$B:$B,T$1)+SUMIFS('Doc Há Pagar | Rodopar 1015'!$J:$J,'Doc Há Pagar | Rodopar 1015'!$A:$A,$B6&$E6&$F6,'Doc Há Pagar | Rodopar 1015'!$B:$B,T$1) -> 0 | U6: =SUMIFS('Doc''s Pagos | Rodopar 108'!$J:$J,'Doc''s Pagos | Rodopar 108'!$A:$A,$B6&$E6&$F6&$J6,'Doc''s Pagos | Rodopar 108'!$B:$B,U$1)+SUMIFS('Doc Há Pagar | Rodopar 1015'!$J:$J,'Doc Há Pagar | Rodopar 1015'!$A:$A,$B6&$E6&$F6,'Doc Há Pagar | Rodopar 1015'!$B:$B,U$1) -> 0 | V6: =SUMIFS('Doc''s Pagos | Rodopar 108'!$J:$J,'Doc''s Pagos | Rodopar 108'!$A:$A,$B6&$E6&$F6&$J6,'Doc''s Pagos | Rodopar 108'!$B:$B,V$1)+SUMIFS('Doc Há Pagar | Rodopar 1015'!$J:$J,'Doc Há Pagar | Rodopar 1015'!$A:$A,$B6&$E6&$F6,'Doc Há Pagar | Rodopar 1015'!$B:$B,V$1) -> 0 | W6: =SUMIFS('Doc''s Pagos | Rodopar 108'!$J:$J,'Doc''s Pagos | Rodopar 108'!$A:$A,$B6&$E6&$F6&$J6,'Doc''s Pagos | Rodopar 108'!$B:$B,W$1)+SUMIFS('Doc Há Pagar | Rodopar 1015'!$J:$J,'Doc Há Pagar | Rodopar 1015'!$A:$A,$B6&$E6&$F6,'Doc Há Pagar | Rodopar 1015'!$B:$B,W$1) -> 0 | X6: =SUMIFS('Doc''s Pagos | Rodopar 108'!$J:$J,'Doc''s Pagos | Rodopar 108'!$A:$A,$B6&$E6&$F6&$J6,'Doc''s Pagos | Rodopar 108'!$B:$B,X$1)+SUMIFS('Doc Há Pagar | Rodopar 1015'!$J:$J,'Doc Há Pagar | Rodopar 1015'!$A:$A,$B6&$E6&$F6,'Doc Há Pagar | Rodopar 1015'!$B:$B,X$1) -> 0 | Y6: =SUMIFS('Doc''s Pagos | Rodopar 108'!$J:$J,'Doc''s Pagos | Rodopar 108'!$A:$A,$B6&$E6&$F6&$J6,'Doc''s Pagos | Rodopar 108'!$B:$B,Y$1)+SUMIFS('Doc Há Pagar | Rodopar 1015'!$J:$J,'Doc Há Pagar | Rodopar 1015'!$A:$A,$B6&$E6&$F6,'Doc Há Pagar | Rodopar 1015'!$B:$B,Y$1) -> 0 | Z6: =SUMIFS('Doc''s Pagos | Rodopar 108'!$J:$J,'Doc''s Pagos | Rodopar 108'!$A:$A,$B6&$E6&$F6&$J6,'Doc''s Pagos | Rodopar 108'!$B:$B,Z$1)+SUMIFS('Doc Há Pagar | Rodopar 1015'!$J:$J,'Doc Há Pagar | Rodopar 1015'!$A:$A,$B6&$E6&$F6,'Doc Há Pagar | Rodopar 1015'!$B:$B,Z$1) -> 0 | ... AD6: =SUMIFS('Doc''s Pagos | Rodopar 108'!$J:$J,'Doc''s Pagos | Rodopar 108'!$A:$A,$B6&$E6&$F6&$J6,'Doc''s Pagos | Rodopar 108'!$B:$B,AD$1)+SUMIFS('Doc Há Pagar | Rodopar 1015'!$J:$J,'Doc Há Pagar | Rodopar 1015'!$A:$A,$B6&$E6&$F6,'Doc Há Pagar | Rodopar 1015'!$B:$B,AD$1) -> 0
A7: =VLOOKUP($E7,Fornecedores!$A:$C,3,0) -> Frota | B7: 145 | C7: =IFERROR(VLOOKUP($E7,Fornecedores!$A:$E,4,0),"") -> Sinistro | D7: =IFERROR(VLOOKUP($E7,Fornecedores!$A:$E,5,0),"") -> Lanternagem | E7: CAMPOS VEICULOS LTDA - PRIME AUTO CENTER | F7: NSE | G7: 43.792.799/0001-09 | H7: 87 | I7: 1000 | J7: 46017 | K7: 46027 | L7: CONTAGEM | M7: MG | N7: 1556 | O7: GABRIEL.ALBINO | Q7: =SUM(R7:AD7)-I7 -> 0 | S7: =SUMIFS('Doc''s Pagos | Rodopar 108'!$J:$J,'Doc''s Pagos | Rodopar 108'!$A:$A,$B7&$E7&$F7&$J7,'Doc''s Pagos | Rodopar 108'!$B:$B,S$1)+SUMIFS('Doc Há Pagar | Rodopar 1015'!$J:$J,'Doc Há Pagar | Rodopar 1015'!$A:$A,$B7&$E7&$F7,'Doc Há Pagar | Rodopar 1015'!$B:$B,S$1) -> 1000 | T7: =SUMIFS('Doc''s Pagos | Rodopar 108'!$J:$J,'Doc''s Pagos | Rodopar 108'!$A:$A,$B7&$E7&$F7&$J7,'Doc''s Pagos | Rodopar 108'!$B:$B,T$1)+SUMIFS('Doc Há Pagar | Rodopar 1015'!$J:$J,'Doc Há Pagar | Rodopar 1015'!$A:$A,$B7&$E7&$F7,'Doc Há Pagar | Rodopar 1015'!$B:$B,T$1) -> 0 | U7: =SUMIFS('Doc''s Pagos | Rodopar 108'!$J:$J,'Doc''s Pagos | Rodopar 108'!$A:$A,$B7&$E7&$F7&$J7,'Doc''s Pagos | Rodopar 108'!$B:$B,U$1)+SUMIFS('Doc Há Pagar | Rodopar 1015'!$J:$J,'Doc Há Pagar | Rodopar 1015'!$A:$A,$B7&$E7&$F7,'Doc Há Pagar | Rodopar 1015'!$B:$B,U$1) -> 0 | V7: =SUMIFS('Doc''s Pagos | Rodopar 108'!$J:$J,'Doc''s Pagos | Rodopar 108'!$A:$A,$B7&$E7&$F7&$J7,'Doc''s Pagos | Rodopar 108'!$B:$B,V$1)+SUMIFS('Doc Há Pagar | Rodopar 1015'!$J:$J,'Doc Há Pagar | Rodopar 1015'!$A:$A,$B7&$E7&$F7,'Doc Há Pagar | Rodopar 1015'!$B:$B,V$1) -> 0 | W7: =SUMIFS('Doc''s Pagos | Rodopar 108'!$J:$J,'Doc''s Pagos | Rodopar 108'!$A:$A,$B7&$E7&$F7&$J7,'Doc''s Pagos | Rodopar 108'!$B:$B,W$1)+SUMIFS('Doc Há Pagar | Rodopar 1015'!$J:$J,'Doc Há Pagar | Rodopar 1015'!$A:$A,$B7&$E7&$F7,'Doc Há Pagar | Rodopar 1015'!$B:$B,W$1) -> 0 | X7: =SUMIFS('Doc''s Pagos | Rodopar 108'!$J:$J,'Doc''s Pagos | Rodopar 108'!$A:$A,$B7&$E7&$F7&$J7,'Doc''s Pagos | Rodopar 108'!$B:$B,X$1)+SUMIFS('Doc Há Pagar | Rodopar 1015'!$J:$J,'Doc Há Pagar | Rodopar 1015'!$A:$A,$B7&$E7&$F7,'Doc Há Pagar | Rodopar 1015'!$B:$B,X$1) -> 0 | Y7: =SUMIFS('Doc''s Pagos | Rodopar 108'!$J:$J,'Doc''s Pagos | Rodopar 108'!$A:$A,$B7&$E7&$F7&$J7,'Doc''s Pagos | Rodopar 108'!$B:$B,Y$1)+SUMIFS('Doc Há Pagar | Rodopar 1015'!$J:$J,'Doc Há Pagar | Rodopar 1015'!$A:$A,$B7&$E7&$F7,'Doc Há Pagar | Rodopar 1015'!$B:$B,Y$1) -> 0 | Z7: =SUMIFS('Doc''s Pagos | Rodopar 108'!$J:$J,'Doc''s Pagos | Rodopar 108'!$A:$A,$B7&$E7&$F7&$J7,'Doc''s Pagos | Rodopar 108'!$B:$B,Z$1)+SUMIFS('Doc Há Pagar | Rodopar 1015'!$J:$J,'Doc Há Pagar | Rodopar 1015'!$A:$A,$B7&$E7&$F7,'Doc Há Pagar | Rodopar 1015'!$B:$B,Z$1) -> 0 | ... AD7: =SUMIFS('Doc''s Pagos | Rodopar 108'!$J:$J,'Doc''s Pagos | Rodopar 108'!$A:$A,$B7&$E7&$F7&$J7,'Doc''s Pagos | Rodopar 108'!$B:$B,AD$1)+SUMIFS('Doc Há Pagar | Rodopar 1015'!$J:$J,'Doc Há Pagar | Rodopar 1015'!$A:$A,$B7&$E7&$F7,'Doc Há Pagar | Rodopar 1015'!$B:$B,AD$1) -> 0
A8: =VLOOKUP($E8,Fornecedores!$A:$C,3,0) -> Frota | B8: 2611814548 | C8: =IFERROR(VLOOKUP($E8,Fornecedores!$A:$E,4,0),"") -> Pedagios | D8: =IFERROR(VLOOKUP($E8,Fornecedores!$A:$E,5,0),"") -> Pedagios | E8: CENTRO DE GESTÃO DE MEIOS DE PAGTOS. S/A | F8: FT | G8: 04.088.208/0001-65 | H8: 87 | I8: 23342.83 | J8: 46025 | K8: 46029 | L8: OSASCO | M8: SP | N8: 2556 | O8: GABRIEL.ALBINO | Q8: =SUM(R8:AD8)-I8 -> 0 | S8: =SUMIFS('Doc''s Pagos | Rodopar 108'!$J:$J,'Doc''s Pagos | Rodopar 108'!$A:$A,$B8&$E8&$F8&$J8,'Doc''s Pagos | Rodopar 108'!$B:$B,S$1)+SUMIFS('Doc Há Pagar | Rodopar 1015'!$J:$J,'Doc Há Pagar | Rodopar 1015'!$A:$A,$B8&$E8&$F8,'Doc Há Pagar | Rodopar 1015'!$B:$B,S$1) -> 23342.83 | T8: =SUMIFS('Doc''s Pagos | Rodopar 108'!$J:$J,'Doc''s Pagos | Rodopar 108'!$A:$A,$B8&$E8&$F8&$J8,'Doc''s Pagos | Rodopar 108'!$B:$B,T$1)+SUMIFS('Doc Há Pagar | Rodopar 1015'!$J:$J,'Doc Há Pagar | Rodopar 1015'!$A:$A,$B8&$E8&$F8,'Doc Há Pagar | Rodopar 1015'!$B:$B,T$1) -> 0 | U8: =SUMIFS('Doc''s Pagos | Rodopar 108'!$J:$J,'Doc''s Pagos | Rodopar 108'!$A:$A,$B8&$E8&$F8&$J8,'Doc''s Pagos | Rodopar 108'!$B:$B,U$1)+SUMIFS('Doc Há Pagar | Rodopar 1015'!$J:$J,'Doc Há Pagar | Rodopar 1015'!$A:$A,$B8&$E8&$F8,'Doc Há Pagar | Rodopar 1015'!$B:$B,U$1) -> 0 | V8: =SUMIFS('Doc''s Pagos | Rodopar 108'!$J:$J,'Doc''s Pagos | Rodopar 108'!$A:$A,$B8&$E8&$F8&$J8,'Doc''s Pagos | Rodopar 108'!$B:$B,V$1)+SUMIFS('Doc Há Pagar | Rodopar 1015'!$J:$J,'Doc Há Pagar | Rodopar 1015'!$A:$A,$B8&$E8&$F8,'Doc Há Pagar | Rodopar 1015'!$B:$B,V$1) -> 0 | W8: =SUMIFS('Doc''s Pagos | Rodopar 108'!$J:$J,'Doc''s Pagos | Rodopar 108'!$A:$A,$B8&$E8&$F8&$J8,'Doc''s Pagos | Rodopar 108'!$B:$B,W$1)+SUMIFS('Doc Há Pagar | Rodopar 1015'!$J:$J,'Doc Há Pagar | Rodopar 1015'!$A:$A,$B8&$E8&$F8,'Doc Há Pagar | Rodopar 1015'!$B:$B,W$1) -> 0 | X8: =SUMIFS('Doc''s Pagos | Rodopar 108'!$J:$J,'Doc''s Pagos | Rodopar 108'!$A:$A,$B8&$E8&$F8&$J8,'Doc''s Pagos | Rodopar 108'!$B:$B,X$1)+SUMIFS('Doc Há Pagar | Rodopar 1015'!$J:$J,'Doc Há Pagar | Rodopar 1015'!$A:$A,$B8&$E8&$F8,'Doc Há Pagar | Rodopar 1015'!$B:$B,X$1) -> 0 | Y8: =SUMIFS('Doc''s Pagos | Rodopar 108'!$J:$J,'Doc''s Pagos | Rodopar 108'!$A:$A,$B8&$E8&$F8&$J8,'Doc''s Pagos | Rodopar 108'!$B:$B,Y$1)+SUMIFS('Doc Há Pagar | Rodopar 1015'!$J:$J,'Doc Há Pagar | Rodopar 1015'!$A:$A,$B8&$E8&$F8,'Doc Há Pagar | Rodopar 1015'!$B:$B,Y$1) -> 0 | Z8: =SUMIFS('Doc''s Pagos | Rodopar 108'!$J:$J,'Doc''s Pagos | Rodopar 108'!$A:$A,$B8&$E8&$F8&$J8,'Doc''s Pagos | Rodopar 108'!$B:$B,Z$1)+SUMIFS('Doc Há Pagar | Rodopar 1015'!$J:$J,'Doc Há Pagar | Rodopar 1015'!$A:$A,$B8&$E8&$F8,'Doc Há Pagar | Rodopar 1015'!$B:$B,Z$1) -> 0 | ... AD8: =SUMIFS('Doc''s Pagos | Rodopar 108'!$J:$J,'Doc''s Pagos | Rodopar 108'!$A:$A,$B8&$E8&$F8&$J8,'Doc''s Pagos | Rodopar 108'!$B:$B,AD$1)+SUMIFS('Doc Há Pagar | Rodopar 1015'!$J:$J,'Doc Há Pagar | Rodopar 1015'!$A:$A,$B8&$E8&$F8,'Doc Há Pagar | Rodopar 1015'!$B:$B,AD$1) -> 0
A9: =VLOOKUP($E9,Fornecedores!$A:$C,3,0) -> Frota | B9: 1420 | C9: =IFERROR(VLOOKUP($E9,Fornecedores!$A:$E,4,0),"") -> MTSR | D9: =IFERROR(VLOOKUP($E9,Fornecedores!$A:$E,5,0),"") -> Tecnologia | E9: AVANSAT TECNOLOGIAS E SERVS EM SEGURANCA LTDA | F9: FT | G9: 02.602.115/0001-81 | H9: 87 | I9: 59176.89 | J9: 46029 | K9: 46030 | L9: PORTO ALEGRE | M9: RS | N9: 2556 | O9: GABRIEL.ALBINO | Q9: =SUM(R9:AD9)-I9 -> 0 | S9: =SUMIFS('Doc''s Pagos | Rodopar 108'!$J:$J,'Doc''s Pagos | Rodopar 108'!$A:$A,$B9&$E9&$F9&$J9,'Doc''s Pagos | Rodopar 108'!$B:$B,S$1)+SUMIFS('Doc Há Pagar | Rodopar 1015'!$J:$J,'Doc Há Pagar | Rodopar 1015'!$A:$A,$B9&$E9&$F9,'Doc Há Pagar | Rodopar 1015'!$B:$B,S$1) -> 0 | T9: =SUMIFS('Doc''s Pagos | Rodopar 108'!$J:$J,'Doc''s Pagos | Rodopar 108'!$A:$A,$B9&$E9&$F9&$J9,'Doc''s Pagos | Rodopar 108'!$B:$B,T$1)+SUMIFS('Doc Há Pagar | Rodopar 1015'!$J:$J,'Doc Há Pagar | Rodopar 1015'!$A:$A,$B9&$E9&$F9,'Doc Há Pagar | Rodopar 1015'!$B:$B,T$1) -> 59176.89 | U9: =SUMIFS('Doc''s Pagos | Rodopar 108'!$J:$J,'Doc''s Pagos | Rodopar 108'!$A:$A,$B9&$E9&$F9&$J9,'Doc''s Pagos | Rodopar 108'!$B:$B,U$1)+SUMIFS('Doc Há Pagar | Rodopar 1015'!$J:$J,'Doc Há Pagar | Rodopar 1015'!$A:$A,$B9&$E9&$F9,'Doc Há Pagar | Rodopar 1015'!$B:$B,U$1) -> 0 | V9: =SUMIFS('Doc''s Pagos | Rodopar 108'!$J:$J,'Doc''s Pagos | Rodopar 108'!$A:$A,$B9&$E9&$F9&$J9,'Doc''s Pagos | Rodopar 108'!$B:$B,V$1)+SUMIFS('Doc Há Pagar | Rodopar 1015'!$J:$J,'Doc Há Pagar | Rodopar 1015'!$A:$A,$B9&$E9&$F9,'Doc Há Pagar | Rodopar 1015'!$B:$B,V$1) -> 0 | W9: =SUMIFS('Doc''s Pagos | Rodopar 108'!$J:$J,'Doc''s Pagos | Rodopar 108'!$A:$A,$B9&$E9&$F9&$J9,'Doc''s Pagos | Rodopar 108'!$B:$B,W$1)+SUMIFS('Doc Há Pagar | Rodopar 1015'!$J:$J,'Doc Há Pagar | Rodopar 1015'!$A:$A,$B9&$E9&$F9,'Doc Há Pagar | Rodopar 1015'!$B:$B,W$1) -> 0 | X9: =SUMIFS('Doc''s Pagos | Rodopar 108'!$J:$J,'Doc''s Pagos | Rodopar 108'!$A:$A,$B9&$E9&$F9&$J9,'Doc''s Pagos | Rodopar 108'!$B:$B,X$1)+SUMIFS('Doc Há Pagar | Rodopar 1015'!$J:$J,'Doc Há Pagar | Rodopar 1015'!$A:$A,$B9&$E9&$F9,'Doc Há Pagar | Rodopar 1015'!$B:$B,X$1) -> 0 | Y9: =SUMIFS('Doc''s Pagos | Rodopar 108'!$J:$J,'Doc''s Pagos | Rodopar 108'!$A:$A,$B9&$E9&$F9&$J9,'Doc''s Pagos | Rodopar 108'!$B:$B,Y$1)+SUMIFS('Doc Há Pagar | Rodopar 1015'!$J:$J,'Doc Há Pagar | Rodopar 1015'!$A:$A,$B9&$E9&$F9,'Doc Há Pagar | Rodopar 1015'!$B:$B,Y$1) -> 0 | Z9: =SUMIFS('Doc''s Pagos | Rodopar 108'!$J:$J,'Doc''s Pagos | Rodopar 108'!$A:$A,$B9&$E9&$F9&$J9,'Doc''s Pagos | Rodopar 108'!$B:$B,Z$1)+SUMIFS('Doc Há Pagar | Rodopar 1015'!$J:$J,'Doc Há Pagar | Rodopar 1015'!$A:$A,$B9&$E9&$F9,'Doc Há Pagar | Rodopar 1015'!$B:$B,Z$1) -> 0 | ... AD9: =SUMIFS('Doc''s Pagos | Rodopar 108'!$J:$J,'Doc''s Pagos | Rodopar 108'!$A:$A,$B9&$E9&$F9&$J9,'Doc''s Pagos | Rodopar 108'!$B:$B,AD$1)+SUMIFS('Doc Há Pagar | Rodopar 1015'!$J:$J,'Doc Há Pagar | Rodopar 1015'!$A:$A,$B9&$E9&$F9,'Doc Há Pagar | Rodopar 1015'!$B:$B,AD$1) -> 0
A10: =VLOOKUP($E10,Fornecedores!$A:$C,3,0) -> Frota | B10: 421 | C10: =IFERROR(VLOOKUP($E10,Fornecedores!$A:$E,4,0),"") -> MTSR | D10: =IFERROR(VLOOKUP($E10,Fornecedores!$A:$E,5,0),"") -> Tecnologia | E10: AVANSAT TECNOLOGIAS E SERVS EM SEGURANCA LTDA | F10: NSE | G10: 02.602.115/0001-81 | H10: 87 | I10: 11929.32 | J10: 46029 | K10: 46030 | L10: PORTO ALEGRE | M10: RS | N10: 2556 | O10: GABRIEL.ALBINO | Q10: =SUM(R10:AD10)-I10 -> 0 | S10: =SUMIFS('Doc''s Pagos | Rodopar 108'!$J:$J,'Doc''s Pagos | Rodopar 108'!$A:$A,$B10&$E10&$F10&$J10,'Doc''s Pagos | Rodopar 108'!$B:$B,S$1)+SUMIFS('Doc Há Pagar | Rodopar 1015'!$J:$J,'Doc Há Pagar | Rodopar 1015'!$A:$A,$B10&$E10&$F10,'Doc Há Pagar | Rodopar 1015'!$B:$B,S$1) -> 0 | T10: =SUMIFS('Doc''s Pagos | Rodopar 108'!$J:$J,'Doc''s Pagos | Rodopar 108'!$A:$A,$B10&$E10&$F10&$J10,'Doc''s Pagos | Rodopar 108'!$B:$B,T$1)+SUMIFS('Doc Há Pagar | Rodopar 1015'!$J:$J,'Doc Há Pagar | Rodopar 1015'!$A:$A,$B10&$E10&$F10,'Doc Há Pagar | Rodopar 1015'!$B:$B,T$1) -> 11929.32 | U10: =SUMIFS('Doc''s Pagos | Rodopar 108'!$J:$J,'Doc''s Pagos | Rodopar 108'!$A:$A,$B10&$E10&$F10&$J10,'Doc''s Pagos | Rodopar 108'!$B:$B,U$1)+SUMIFS('Doc Há Pagar | Rodopar 1015'!$J:$J,'Doc Há Pagar | Rodopar 1015'!$A:$A,$B10&$E10&$F10,'Doc Há Pagar | Rodopar 1015'!$B:$B,U$1) -> 0 | V10: =SUMIFS('Doc''s Pagos | Rodopar 108'!$J:$J,'Doc''s Pagos | Rodopar 108'!$A:$A,$B10&$E10&$F10&$J10,'Doc''s Pagos | Rodopar 108'!$B:$B,V$1)+SUMIFS('Doc Há Pagar | Rodopar 1015'!$J:$J,'Doc Há Pagar | Rodopar 1015'!$A:$A,$B10&$E10&$F10,'Doc Há Pagar | Rodopar 1015'!$B:$B,V$1) -> 0 | W10: =SUMIFS('Doc''s Pagos | Rodopar 108'!$J:$J,'Doc''s Pagos | Rodopar 108'!$A:$A,$B10&$E10&$F10&$J10,'Doc''s Pagos | Rodopar 108'!$B:$B,W$1)+SUMIFS('Doc Há Pagar | Rodopar 1015'!$J:$J,'Doc Há Pagar | Rodopar 1015'!$A:$A,$B10&$E10&$F10,'Doc Há Pagar | Rodopar 1015'!$B:$B,W$1) -> 0 | X10: =SUMIFS('Doc''s Pagos | Rodopar 108'!$J:$J,'Doc''s Pagos | Rodopar 108'!$A:$A,$B10&$E10&$F10&$J10,'Doc''s Pagos | Rodopar 108'!$B:$B,X$1)+SUMIFS('Doc Há Pagar | Rodopar 1015'!$J:$J,'Doc Há Pagar | Rodopar 1015'!$A:$A,$B10&$E10&$F10,'Doc Há Pagar | Rodopar 1015'!$B:$B,X$1) -> 0 | Y10: =SUMIFS('Doc''s Pagos | Rodopar 108'!$J:$J,'Doc''s Pagos | Rodopar 108'!$A:$A,$B10&$E10&$F10&$J10,'Doc''s Pagos | Rodopar 108'!$B:$B,Y$1)+SUMIFS('Doc Há Pagar | Rodopar 1015'!$J:$J,'Doc Há Pagar | Rodopar 1015'!$A:$A,$B10&$E10&$F10,'Doc Há Pagar | Rodopar 1015'!$B:$B,Y$1) -> 0 | Z10: =SUMIFS('Doc''s Pagos | Rodopar 108'!$J:$J,'Doc''s Pagos | Rodopar 108'!$A:$A,$B10&$E10&$F10&$J10,'Doc''s Pagos | Rodopar 108'!$B:$B,Z$1)+SUMIFS('Doc Há Pagar | Rodopar 1015'!$J:$J,'Doc Há Pagar | Rodopar 1015'!$A:$A,$B10&$E10&$F10,'Doc Há Pagar | Rodopar 1015'!$B:$B,Z$1) -> 0 | ... AD10: =SUMIFS('Doc''s Pagos | Rodopar 108'!$J:$J,'Doc''s Pagos | Rodopar 108'!$A:$A,$B10&$E10&$F10&$J10,'Doc''s Pagos | Rodopar 108'!$B:$B,AD$1)+SUMIFS('Doc Há Pagar | Rodopar 1015'!$J:$J,'Doc Há Pagar | Rodopar 1015'!$A:$A,$B10&$E10&$F10,'Doc Há Pagar | Rodopar 1015'!$B:$B,AD$1) -> 0
A11: =VLOOKUP($E11,Fornecedores!$A:$C,3,0) -> Frota | B11: 422 | C11: =IFERROR(VLOOKUP($E11,Fornecedores!$A:$E,4,0),"") -> MTSR | D11: =IFERROR(VLOOKUP($E11,Fornecedores!$A:$E,5,0),"") -> Tecnologia | E11: AVANSAT TECNOLOGIAS E SERVS EM SEGURANCA LTDA | F11: NSE | G11: 02.602.115/0001-81 | H11: 87 | I11: 9126.74 | J11: 46029 | K11: 46030 | L11: PORTO ALEGRE | M11: RS | N11: 2556 | O11: GABRIEL.ALBINO | Q11: =SUM(R11:AD11)-I11 -> 0 | S11: =SUMIFS('Doc''s Pagos | Rodopar 108'!$J:$J,'Doc''s Pagos | Rodopar 108'!$A:$A,$B11&$E11&$F11&$J11,'Doc''s Pagos | Rodopar 108'!$B:$B,S$1)+SUMIFS('Doc Há Pagar | Rodopar 1015'!$J:$J,'Doc Há Pagar | Rodopar 1015'!$A:$A,$B11&$E11&$F11,'Doc Há Pagar | Rodopar 1015'!$B:$B,S$1) -> 0 | T11: =SUMIFS('Doc''s Pagos | Rodopar 108'!$J:$J,'Doc''s Pagos | Rodopar 108'!$A:$A,$B11&$E11&$F11&$J11,'Doc''s Pagos | Rodopar 108'!$B:$B,T$1)+SUMIFS('Doc Há Pagar | Rodopar 1015'!$J:$J,'Doc Há Pagar | Rodopar 1015'!$A:$A,$B11&$E11&$F11,'Doc Há Pagar | Rodopar 1015'!$B:$B,T$1) -> 9126.74 | U11: =SUMIFS('Doc''s Pagos | Rodopar 108'!$J:$J,'Doc''s Pagos | Rodopar 108'!$A:$A,$B11&$E11&$F11&$J11,'Doc''s Pagos | Rodopar 108'!$B:$B,U$1)+SUMIFS('Doc Há Pagar | Rodopar 1015'!$J:$J,'Doc Há Pagar | Rodopar 1015'!$A:$A,$B11&$E11&$F11,'Doc Há Pagar | Rodopar 1015'!$B:$B,U$1) -> 0 | V11: =SUMIFS('Doc''s Pagos | Rodopar 108'!$J:$J,'Doc''s Pagos | Rodopar 108'!$A:$A,$B11&$E11&$F11&$J11,'Doc''s Pagos | Rodopar 108'!$B:$B,V$1)+SUMIFS('Doc Há Pagar | Rodopar 1015'!$J:$J,'Doc Há Pagar | Rodopar 1015'!$A:$A,$B11&$E11&$F11,'Doc Há Pagar | Rodopar 1015'!$B:$B,V$1) -> 0 | W11: =SUMIFS('Doc''s Pagos | Rodopar 108'!$J:$J,'Doc''s Pagos | Rodopar 108'!$A:$A,$B11&$E11&$F11&$J11,'Doc''s Pagos | Rodopar 108'!$B:$B,W$1)+SUMIFS('Doc Há Pagar | Rodopar 1015'!$J:$J,'Doc Há Pagar | Rodopar 1015'!$A:$A,$B11&$E11&$F11,'Doc Há Pagar | Rodopar 1015'!$B:$B,W$1) -> 0 | X11: =SUMIFS('Doc''s Pagos | Rodopar 108'!$J:$J,'Doc''s Pagos | Rodopar 108'!$A:$A,$B11&$E11&$F11&$J11,'Doc''s Pagos | Rodopar 108'!$B:$B,X$1)+SUMIFS('Doc Há Pagar | Rodopar 1015'!$J:$J,'Doc Há Pagar | Rodopar 1015'!$A:$A,$B11&$E11&$F11,'Doc Há Pagar | Rodopar 1015'!$B:$B,X$1) -> 0 | Y11: =SUMIFS('Doc''s Pagos | Rodopar 108'!$J:$J,'Doc''s Pagos | Rodopar 108'!$A:$A,$B11&$E11&$F11&$J11,'Doc''s Pagos | Rodopar 108'!$B:$B,Y$1)+SUMIFS('Doc Há Pagar | Rodopar 1015'!$J:$J,'Doc Há Pagar | Rodopar 1015'!$A:$A,$B11&$E11&$F11,'Doc Há Pagar | Rodopar 1015'!$B:$B,Y$1) -> 0 | Z11: =SUMIFS('Doc''s Pagos | Rodopar 108'!$J:$J,'Doc''s Pagos | Rodopar 108'!$A:$A,$B11&$E11&$F11&$J11,'Doc''s Pagos | Rodopar 108'!$B:$B,Z$1)+SUMIFS('Doc Há Pagar | Rodopar 1015'!$J:$J,'Doc Há Pagar | Rodopar 1015'!$A:$A,$B11&$E11&$F11,'Doc Há Pagar | Rodopar 1015'!$B:$B,Z$1) -> 0 | ... AD11: =SUMIFS('Doc''s Pagos | Rodopar 108'!$J:$J,'Doc''s Pagos | Rodopar 108'!$A:$A,$B11&$E11&$F11&$J11,'Doc''s Pagos | Rodopar 108'!$B:$B,AD$1)+SUMIFS('Doc Há Pagar | Rodopar 1015'!$J:$J,'Doc Há Pagar | Rodopar 1015'!$A:$A,$B11&$E11&$F11,'Doc Há Pagar | Rodopar 1015'!$B:$B,AD$1) -> 0
A12: =VLOOKUP($E12,Fornecedores!$A:$C,3,0) -> Frota | B12: 746021 | C12: =IFERROR(VLOOKUP($E12,Fornecedores!$A:$E,4,0),"") -> Telemetria | D12: =IFERROR(VLOOKUP($E12,Fornecedores!$A:$E,5,0),"") -> Telemetria | E12: SASCAR TECNOLOGIA E SEGURANÇA AUTOMOTICA S/A | F12: NSE | G12: 03.112.879/0001-51 | H12: 87 | I12: 357.45 | J12: 46030 | K12: 46031 | L12: SANTANA DE PARNAIBA | M12: SP | N12: 2556 | O12: GABRIEL.ALBINO | Q12: =SUM(R12:AD12)-I12 -> 0 | S12: =SUMIFS('Doc''s Pagos | Rodopar 108'!$J:$J,'Doc''s Pagos | Rodopar 108'!$A:$A,$B12&$E12&$F12&$J12,'Doc''s Pagos | Rodopar 108'!$B:$B,S$1)+SUMIFS('Doc Há Pagar | Rodopar 1015'!$J:$J,'Doc Há Pagar | Rodopar 1015'!$A:$A,$B12&$E12&$F12,'Doc Há Pagar | Rodopar 1015'!$B:$B,S$1) -> 0 | T12: =SUMIFS('Doc''s Pagos | Rodopar 108'!$J:$J,'Doc''s Pagos | Rodopar 108'!$A:$A,$B12&$E12&$F12&$J12,'Doc''s Pagos | Rodopar 108'!$B:$B,T$1)+SUMIFS('Doc Há Pagar | Rodopar 1015'!$J:$J,'Doc Há Pagar | Rodopar 1015'!$A:$A,$B12&$E12&$F12,'Doc Há Pagar | Rodopar 1015'!$B:$B,T$1) -> 357.45 | U12: =SUMIFS('Doc''s Pagos | Rodopar 108'!$J:$J,'Doc''s Pagos | Rodopar 108'!$A:$A,$B12&$E12&$F12&$J12,'Doc''s Pagos | Rodopar 108'!$B:$B,U$1)+SUMIFS('Doc Há Pagar | Rodopar 1015'!$J:$J,'Doc Há Pagar | Rodopar 1015'!$A:$A,$B12&$E12&$F12,'Doc Há Pagar | Rodopar 1015'!$B:$B,U$1) -> 0 | V12: =SUMIFS('Doc''s Pagos | Rodopar 108'!$J:$J,'Doc''s Pagos | Rodopar 108'!$A:$A,$B12&$E12&$F12&$J12,'Doc''s Pagos | Rodopar 108'!$B:$B,V$1)+SUMIFS('Doc Há Pagar | Rodopar 1015'!$J:$J,'Doc Há Pagar | Rodopar 1015'!$A:$A,$B12&$E12&$F12,'Doc Há Pagar | Rodopar 1015'!$B:$B,V$1) -> 0 | W12: =SUMIFS('Doc''s Pagos | Rodopar 108'!$J:$J,'Doc''s Pagos | Rodopar 108'!$A:$A,$B12&$E12&$F12&$J12,'Doc''s Pagos | Rodopar 108'!$B:$B,W$1)+SUMIFS('Doc Há Pagar | Rodopar 1015'!$J:$J,'Doc Há Pagar | Rodopar 1015'!$A:$A,$B12&$E12&$F12,'Doc Há Pagar | Rodopar 1015'!$B:$B,W$1) -> 0 | X12: =SUMIFS('Doc''s Pagos | Rodopar 108'!$J:$J,'Doc''s Pagos | Rodopar 108'!$A:$A,$B12&$E12&$F12&$J12,'Doc''s Pagos | Rodopar 108'!$B:$B,X$1)+SUMIFS('Doc Há Pagar | Rodopar 1015'!$J:$J,'Doc Há Pagar | Rodopar 1015'!$A:$A,$B12&$E12&$F12,'Doc Há Pagar | Rodopar 1015'!$B:$B,X$1) -> 0 | Y12: =SUMIFS('Doc''s Pagos | Rodopar 108'!$J:$J,'Doc''s Pagos | Rodopar 108'!$A:$A,$B12&$E12&$F12&$J12,'Doc''s Pagos | Rodopar 108'!$B:$B,Y$1)+SUMIFS('Doc Há Pagar | Rodopar 1015'!$J:$J,'Doc Há Pagar | Rodopar 1015'!$A:$A,$B12&$E12&$F12,'Doc Há Pagar | Rodopar 1015'!$B:$B,Y$1) -> 0 | Z12: =SUMIFS('Doc''s Pagos | Rodopar 108'!$J:$J,'Doc''s Pagos | Rodopar 108'!$A:$A,$B12&$E12&$F12&$J12,'Doc''s Pagos | Rodopar 108'!$B:$B,Z$1)+SUMIFS('Doc Há Pagar | Rodopar 1015'!$J:$J,'Doc Há Pagar | Rodopar 1015'!$A:$A,$B12&$E12&$F12,'Doc Há Pagar | Rodopar 1015'!$B:$B,Z$1) -> 0 | ... AD12: =SUMIFS('Doc''s Pagos | Rodopar 108'!$J:$J,'Doc''s Pagos | Rodopar 108'!$A:$A,$B12&$E12&$F12&$J12,'Doc''s Pagos | Rodopar 108'!$B:$B,AD$1)+SUMIFS('Doc Há Pagar | Rodopar 1015'!$J:$J,'Doc Há Pagar | Rodopar 1015'!$A:$A,$B12&$E12&$F12,'Doc Há Pagar | Rodopar 1015'!$B:$B,AD$1) -> 0
A13: =VLOOKUP($E13,Fornecedores!$A:$C,3,0) -> Frota | B13: AGMTZ-10840198 | C13: =IFERROR(VLOOKUP($E13,Fornecedores!$A:$E,4,0),"") -> OPE Merchandising | D13: =IFERROR(VLOOKUP($E13,Fornecedores!$A:$E,5,0),"") -> Locação | E13: LOCALIZA RENT A CAR SA | F13: FT | G13: 16.670.085/0001-55 | H13: 87 | I13: 588.97 | J13: 46031 | K13: 46035 | L13: BELO HORIZONTE | M13: MG | N13: 1556 | O13: GABRIEL.ALBINO | Q13: =SUM(R13:AD13)-I13 -> 0 | S13: =SUMIFS('Doc''s Pagos | Rodopar 108'!$J:$J,'Doc''s Pagos | Rodopar 108'!$A:$A,$B13&$E13&$F13&$J13,'Doc''s Pagos | Rodopar 108'!$B:$B,S$1)+SUMIFS('Doc Há Pagar | Rodopar 1015'!$J:$J,'Doc Há Pagar | Rodopar 1015'!$A:$A,$B13&$E13&$F13,'Doc Há Pagar | Rodopar 1015'!$B:$B,S$1) -> 588.97 | T13: =SUMIFS('Doc''s Pagos | Rodopar 108'!$J:$J,'Doc''s Pagos | Rodopar 108'!$A:$A,$B13&$E13&$F13&$J13,'Doc''s Pagos | Rodopar 108'!$B:$B,T$1)+SUMIFS('Doc Há Pagar | Rodopar 1015'!$J:$J,'Doc Há Pagar | Rodopar 1015'!$A:$A,$B13&$E13&$F13,'Doc Há Pagar | Rodopar 1015'!$B:$B,T$1) -> 0 | U13: =SUMIFS('Doc''s Pagos | Rodopar 108'!$J:$J,'Doc''s Pagos | Rodopar 108'!$A:$A,$B13&$E13&$F13&$J13,'Doc''s Pagos | Rodopar 108'!$B:$B,U$1)+SUMIFS('Doc Há Pagar | Rodopar 1015'!$J:$J,'Doc Há Pagar | Rodopar 1015'!$A:$A,$B13&$E13&$F13,'Doc Há Pagar | Rodopar 1015'!$B:$B,U$1) -> 0 | V13: =SUMIFS('Doc''s Pagos | Rodopar 108'!$J:$J,'Doc''s Pagos | Rodopar 108'!$A:$A,$B13&$E13&$F13&$J13,'Doc''s Pagos | Rodopar 108'!$B:$B,V$1)+SUMIFS('Doc Há Pagar | Rodopar 1015'!$J:$J,'Doc Há Pagar | Rodopar 1015'!$A:$A,$B13&$E13&$F13,'Doc Há Pagar | Rodopar 1015'!$B:$B,V$1) -> 0 | W13: =SUMIFS('Doc''s Pagos | Rodopar 108'!$J:$J,'Doc''s Pagos | Rodopar 108'!$A:$A,$B13&$E13&$F13&$J13,'Doc''s Pagos | Rodopar 108'!$B:$B,W$1)+SUMIFS('Doc Há Pagar | Rodopar 1015'!$J:$J,'Doc Há Pagar | Rodopar 1015'!$A:$A,$B13&$E13&$F13,'Doc Há Pagar | Rodopar 1015'!$B:$B,W$1) -> 0 | X13: =SUMIFS('Doc''s Pagos | Rodopar 108'!$J:$J,'Doc''s Pagos | Rodopar 108'!$A:$A,$B13&$E13&$F13&$J13,'Doc''s Pagos | Rodopar 108'!$B:$B,X$1)+SUMIFS('Doc Há Pagar | Rodopar 1015'!$J:$J,'Doc Há Pagar | Rodopar 1015'!$A:$A,$B13&$E13&$F13,'Doc Há Pagar | Rodopar 1015'!$B:$B,X$1) -> 0 | Y13: =SUMIFS('Doc''s Pagos | Rodopar 108'!$J:$J,'Doc''s Pagos | Rodopar 108'!$A:$A,$B13&$E13&$F13&$J13,'Doc''s Pagos | Rodopar 108'!$B:$B,Y$1)+SUMIFS('Doc Há Pagar | Rodopar 1015'!$J:$J,'Doc Há Pagar | Rodopar 1015'!$A:$A,$B13&$E13&$F13,'Doc Há Pagar | Rodopar 1015'!$B:$B,Y$1) -> 0 | Z13: =SUMIFS('Doc''s Pagos | Rodopar 108'!$J:$J,'Doc''s Pagos | Rodopar 108'!$A:$A,$B13&$E13&$F13&$J13,'Doc''s Pagos | Rodopar 108'!$B:$B,Z$1)+SUMIFS('Doc Há Pagar | Rodopar 1015'!$J:$J,'Doc Há Pagar | Rodopar 1015'!$A:$A,$B13&$E13&$F13,'Doc Há Pagar | Rodopar 1015'!$B:$B,Z$1) -> 0 | ... AD13: =SUMIFS('Doc''s Pagos | Rodopar 108'!$J:$J,'Doc''s Pagos | Rodopar 108'!$A:$A,$B13&$E13&$F13&$J13,'Doc''s Pagos | Rodopar 108'!$B:$B,AD$1)+SUMIFS('Doc Há Pagar | Rodopar 1015'!$J:$J,'Doc Há Pagar | Rodopar 1015'!$A:$A,$B13&$E13&$F13,'Doc Há Pagar | Rodopar 1015'!$B:$B,AD$1) -> 0
A14: =VLOOKUP($E14,Fornecedores!$A:$C,3,0) -> Frota | B14: 183264 | C14: =IFERROR(VLOOKUP($E14,Fornecedores!$A:$E,4,0),"") -> Manutenção | D14: =IFERROR(VLOOKUP($E14,Fornecedores!$A:$E,5,0),"") -> Vans | E14: MINAS MAQUINAS SA | JUIZ DE FORA | F14: NFE | G14: 21.549.423/0001-35 | H14: 87 | I14: 2526.91 | J14: 46031 | K14: 46035 | L14: JUIZ DE FORA | M14: MG | N14: 1556 | O14: GABRIEL.ALBINO | Q14: =SUM(R14:AD14)-I14 -> 0 | S14: =SUMIFS('Doc''s Pagos | Rodopar 108'!$J:$J,'Doc''s Pagos | Rodopar 108'!$A:$A,$B14&$E14&$F14&$J14,'Doc''s Pagos | Rodopar 108'!$B:$B,S$1)+SUMIFS('Doc Há Pagar | Rodopar 1015'!$J:$J,'Doc Há Pagar | Rodopar 1015'!$A:$A,$B14&$E14&$F14,'Doc Há Pagar | Rodopar 1015'!$B:$B,S$1) -> 0 | T14: =SUMIFS('Doc''s Pagos | Rodopar 108'!$J:$J,'Doc''s Pagos | Rodopar 108'!$A:$A,$B14&$E14&$F14&$J14,'Doc''s Pagos | Rodopar 108'!$B:$B,T$1)+SUMIFS('Doc Há Pagar | Rodopar 1015'!$J:$J,'Doc Há Pagar | Rodopar 1015'!$A:$A,$B14&$E14&$F14,'Doc Há Pagar | Rodopar 1015'!$B:$B,T$1) -> 2526.91 | U14: =SUMIFS('Doc''s Pagos | Rodopar 108'!$J:$J,'Doc''s Pagos | Rodopar 108'!$A:$A,$B14&$E14&$F14&$J14,'Doc''s Pagos | Rodopar 108'!$B:$B,U$1)+SUMIFS('Doc Há Pagar | Rodopar 1015'!$J:$J,'Doc Há Pagar | Rodopar 1015'!$A:$A,$B14&$E14&$F14,'Doc Há Pagar | Rodopar 1015'!$B:$B,U$1) -> 0 | V14: =SUMIFS('Doc''s Pagos | Rodopar 108'!$J:$J,'Doc''s Pagos | Rodopar 108'!$A:$A,$B14&$E14&$F14&$J14,'Doc''s Pagos | Rodopar 108'!$B:$B,V$1)+SUMIFS('Doc Há Pagar | Rodopar 1015'!$J:$J,'Doc Há Pagar | Rodopar 1015'!$A:$A,$B14&$E14&$F14,'Doc Há Pagar | Rodopar 1015'!$B:$B,V$1) -> 0 | W14: =SUMIFS('Doc''s Pagos | Rodopar 108'!$J:$J,'Doc''s Pagos | Rodopar 108'!$A:$A,$B14&$E14&$F14&$J14,'Doc''s Pagos | Rodopar 108'!$B:$B,W$1)+SUMIFS('Doc Há Pagar | Rodopar 1015'!$J:$J,'Doc Há Pagar | Rodopar 1015'!$A:$A,$B14&$E14&$F14,'Doc Há Pagar | Rodopar 1015'!$B:$B,W$1) -> 0 | X14: =SUMIFS('Doc''s Pagos | Rodopar 108'!$J:$J,'Doc''s Pagos | Rodopar 108'!$A:$A,$B14&$E14&$F14&$J14,'Doc''s Pagos | Rodopar 108'!$B:$B,X$1)+SUMIFS('Doc Há Pagar | Rodopar 1015'!$J:$J,'Doc Há Pagar | Rodopar 1015'!$A:$A,$B14&$E14&$F14,'Doc Há Pagar | Rodopar 1015'!$B:$B,X$1) -> 0 | Y14: =SUMIFS('Doc''s Pagos | Rodopar 108'!$J:$J,'Doc''s Pagos | Rodopar 108'!$A:$A,$B14&$E14&$F14&$J14,'Doc''s Pagos | Rodopar 108'!$B:$B,Y$1)+SUMIFS('Doc Há Pagar | Rodopar 1015'!$J:$J,'Doc Há Pagar | Rodopar 1015'!$A:$A,$B14&$E14&$F14,'Doc Há Pagar | Rodopar 1015'!$B:$B,Y$1) -> 0 | Z14: =SUMIFS('Doc''s Pagos | Rodopar 108'!$J:$J,'Doc''s Pagos | Rodopar 108'!$A:$A,$B14&$E14&$F14&$J14,'Doc''s Pagos | Rodopar 108'!$B:$B,Z$1)+SUMIFS('Doc Há Pagar | Rodopar 1015'!$J:$J,'Doc Há Pagar | Rodopar 1015'!$A:$A,$B14&$E14&$F14,'Doc Há Pagar | Rodopar 1015'!$B:$B,Z$1) -> 0 | ... AD14: =SUMIFS('Doc''s Pagos | Rodopar 108'!$J:$J,'Doc''s Pagos | Rodopar 108'!$A:$A,$B14&$E14&$F14&$J14,'Doc''s Pagos | Rodopar 108'!$B:$B,AD$1)+SUMIFS('Doc Há Pagar | Rodopar 1015'!$J:$J,'Doc Há Pagar | Rodopar 1015'!$A:$A,$B14&$E14&$F14,'Doc Há Pagar | Rodopar 1015'!$B:$B,AD$1) -> 0
A15: =VLOOKUP($E15,Fornecedores!$A:$C,3,0) -> Frota | B15: 6120 | C15: =IFERROR(VLOOKUP($E15,Fornecedores!$A:$E,4,0),"") -> Manutenção | D15: =IFERROR(VLOOKUP($E15,Fornecedores!$A:$E,5,0),"") -> Peças E Serviços | E15: LL BATERIAS E AUTO-ELETRICA LTDA | F15: NFE | G15: 12.118.555/0001-11 | H15: 87 | I15: 435 | J15: 46031 | K15: 46034 | L15: CONTAGEM | M15: MG | N15: 1556 | O15: GABRIEL.ALBINO | Q15: =SUM(R15:AD15)-I15 -> 0 | S15: =SUMIFS('Doc''s Pagos | Rodopar 108'!$J:$J,'Doc''s Pagos | Rodopar 108'!$A:$A,$B15&$E15&$F15&$J15,'Doc''s Pagos | Rodopar 108'!$B:$B,S$1)+SUMIFS('Doc Há Pagar | Rodopar 1015'!$J:$J,'Doc Há Pagar | Rodopar 1015'!$A:$A,$B15&$E15&$F15,'Doc Há Pagar | Rodopar 1015'!$B:$B,S$1) -> 0 | T15: =SUMIFS('Doc''s Pagos | Rodopar 108'!$J:$J,'Doc''s Pagos | Rodopar 108'!$A:$A,$B15&$E15&$F15&$J15,'Doc''s Pagos | Rodopar 108'!$B:$B,T$1)+SUMIFS('Doc Há Pagar | Rodopar 1015'!$J:$J,'Doc Há Pagar | Rodopar 1015'!$A:$A,$B15&$E15&$F15,'Doc Há Pagar | Rodopar 1015'!$B:$B,T$1) -> 435 | U15: =SUMIFS('Doc''s Pagos | Rodopar 108'!$J:$J,'Doc''s Pagos | Rodopar 108'!$A:$A,$B15&$E15&$F15&$J15,'Doc''s Pagos | Rodopar 108'!$B:$B,U$1)+SUMIFS('Doc Há Pagar | Rodopar 1015'!$J:$J,'Doc Há Pagar | Rodopar 1015'!$A:$A,$B15&$E15&$F15,'Doc Há Pagar | Rodopar 1015'!$B:$B,U$1) -> 0 | V15: =SUMIFS('Doc''s Pagos | Rodopar 108'!$J:$J,'Doc''s Pagos | Rodopar 108'!$A:$A,$B15&$E15&$F15&$J15,'Doc''s Pagos | Rodopar 108'!$B:$B,V$1)+SUMIFS('Doc Há Pagar | Rodopar 1015'!$J:$J,'Doc Há Pagar | Rodopar 1015'!$A:$A,$B15&$E15&$F15,'Doc Há Pagar | Rodopar 1015'!$B:$B,V$1) -> 0 | W15: =SUMIFS('Doc''s Pagos | Rodopar 108'!$J:$J,'Doc''s Pagos | Rodopar 108'!$A:$A,$B15&$E15&$F15&$J15,'Doc''s Pagos | Rodopar 108'!$B:$B,W$1)+SUMIFS('Doc Há Pagar | Rodopar 1015'!$J:$J,'Doc Há Pagar | Rodopar 1015'!$A:$A,$B15&$E15&$F15,'Doc Há Pagar | Rodopar 1015'!$B:$B,W$1) -> 0 | X15: =SUMIFS('Doc''s Pagos | Rodopar 108'!$J:$J,'Doc''s Pagos | Rodopar 108'!$A:$A,$B15&$E15&$F15&$J15,'Doc''s Pagos | Rodopar 108'!$B:$B,X$1)+SUMIFS('Doc Há Pagar | Rodopar 1015'!$J:$J,'Doc Há Pagar | Rodopar 1015'!$A:$A,$B15&$E15&$F15,'Doc Há Pagar | Rodopar 1015'!$B:$B,X$1) -> 0 | Y15: =SUMIFS('Doc''s Pagos | Rodopar 108'!$J:$J,'Doc''s Pagos | Rodopar 108'!$A:$A,$B15&$E15&$F15&$J15,'Doc''s Pagos | Rodopar 108'!$B:$B,Y$1)+SUMIFS('Doc Há Pagar | Rodopar 1015'!$J:$J,'Doc Há Pagar | Rodopar 1015'!$A:$A,$B15&$E15&$F15,'Doc Há Pagar | Rodopar 1015'!$B:$B,Y$1) -> 0 | Z15: =SUMIFS('Doc''s Pagos | Rodopar 108'!$J:$J,'Doc''s Pagos | Rodopar 108'!$A:$A,$B15&$E15&$F15&$J15,'Doc''s Pagos | Rodopar 108'!$B:$B,Z$1)+SUMIFS('Doc Há Pagar | Rodopar 1015'!$J:$J,'Doc Há Pagar | Rodopar 1015'!$A:$A,$B15&$E15&$F15,'Doc Há Pagar | Rodopar 1015'!$B:$B,Z$1) -> 0 | ... AD15: =SUMIFS('Doc''s Pagos | Rodopar 108'!$J:$J,'Doc''s Pagos | Rodopar 108'!$A:$A,$B15&$E15&$F15&$J15,'Doc''s Pagos | Rodopar 108'!$B:$B,AD$1)+SUMIFS('Doc Há Pagar | Rodopar 1015'!$J:$J,'Doc Há Pagar | Rodopar 1015'!$A:$A,$B15&$E15&$F15,'Doc Há Pagar | Rodopar 1015'!$B:$B,AD$1) -> 0
A16: =VLOOKUP($E16,Fornecedores!$A:$C,3,0) -> Frota | B16: 2805 | C16: =IFERROR(VLOOKUP($E16,Fornecedores!$A:$E,4,0),"") -> Pneus | D16: =IFERROR(VLOOKUP($E16,Fornecedores!$A:$E,5,0),"") -> Tecnologia | E16: OPENSYSTECH SERVICOS DE MANUTENCAO DE SISTEMAS LTDA | F16: NFS | G16: 23.756.723/0001-10 | H16: 87 | I16: 936.1 | J16: 46031 | K16: 46037 | L16: SAO PAULO | M16: SP | N16: 2949 | O16: JEFFERSON.LIRA | Q16: =SUM(R16:AD16)-I16 -> 0 | S16: =SUMIFS('Doc''s Pagos | Rodopar 108'!$J:$J,'Doc''s Pagos | Rodopar 108'!$A:$A,$B16&$E16&$F16&$J16,'Doc''s Pagos | Rodopar 108'!$B:$B,S$1)+SUMIFS('Doc Há Pagar | Rodopar 1015'!$J:$J,'Doc Há Pagar | Rodopar 1015'!$A:$A,$B16&$E16&$F16,'Doc Há Pagar | Rodopar 1015'!$B:$B,S$1) -> 0 | T16: =SUMIFS('Doc''s Pagos | Rodopar 108'!$J:$J,'Doc''s Pagos | Rodopar 108'!$A:$A,$B16&$E16&$F16&$J16,'Doc''s Pagos | Rodopar 108'!$B:$B,T$1)+SUMIFS('Doc Há Pagar | Rodopar 1015'!$J:$J,'Doc Há Pagar | Rodopar 1015'!$A:$A,$B16&$E16&$F16,'Doc Há Pagar | Rodopar 1015'!$B:$B,T$1) -> 936.1 | U16: =SUMIFS('Doc''s Pagos | Rodopar 108'!$J:$J,'Doc''s Pagos | Rodopar 108'!$A:$A,$B16&$E16&$F16&$J16,'Doc''s Pagos | Rodopar 108'!$B:$B,U$1)+SUMIFS('Doc Há Pagar | Rodopar 1015'!$J:$J,'Doc Há Pagar | Rodopar 1015'!$A:$A,$B16&$E16&$F16,'Doc Há Pagar | Rodopar 1015'!$B:$B,U$1) -> 0 | V16: =SUMIFS('Doc''s Pagos | Rodopar 108'!$J:$J,'Doc''s Pagos | Rodopar 108'!$A:$A,$B16&$E16&$F16&$J16,'Doc''s Pagos | Rodopar 108'!$B:$B,V$1)+SUMIFS('Doc Há Pagar | Rodopar 1015'!$J:$J,'Doc Há Pagar | Rodopar 1015'!$A:$A,$B16&$E16&$F16,'Doc Há Pagar | Rodopar 1015'!$B:$B,V$1) -> 0 | W16: =SUMIFS('Doc''s Pagos | Rodopar 108'!$J:$J,'Doc''s Pagos | Rodopar 108'!$A:$A,$B16&$E16&$F16&$J16,'Doc''s Pagos | Rodopar 108'!$B:$B,W$1)+SUMIFS('Doc Há Pagar | Rodopar 1015'!$J:$J,'Doc Há Pagar | Rodopar 1015'!$A:$A,$B16&$E16&$F16,'Doc Há Pagar | Rodopar 1015'!$B:$B,W$1) -> 0 | X16: =SUMIFS('Doc''s Pagos | Rodopar 108'!$J:$J,'Doc''s Pagos | Rodopar 108'!$A:$A,$B16&$E16&$F16&$J16,'Doc''s Pagos | Rodopar 108'!$B:$B,X$1)+SUMIFS('Doc Há Pagar | Rodopar 1015'!$J:$J,'Doc Há Pagar | Rodopar 1015'!$A:$A,$B16&$E16&$F16,'Doc Há Pagar | Rodopar 1015'!$B:$B,X$1) -> 0 | Y16: =SUMIFS('Doc''s Pagos | Rodopar 108'!$J:$J,'Doc''s Pagos | Rodopar 108'!$A:$A,$B16&$E16&$F16&$J16,'Doc''s Pagos | Rodopar 108'!$B:$B,Y$1)+SUMIFS('Doc Há Pagar | Rodopar 1015'!$J:$J,'Doc Há Pagar | Rodopar 1015'!$A:$A,$B16&$E16&$F16,'Doc Há Pagar | Rodopar 1015'!$B:$B,Y$1) -> 0 | Z16: =SUMIFS('Doc''s Pagos | Rodopar 108'!$J:$J,'Doc''s Pagos | Rodopar 108'!$A:$A,$B16&$E16&$F16&$J16,'Doc''s Pagos | Rodopar 108'!$B:$B,Z$1)+SUMIFS('Doc Há Pagar | Rodopar 1015'!$J:$J,'Doc Há Pagar | Rodopar 1015'!$A:$A,$B16&$E16&$F16,'Doc Há Pagar | Rodopar 1015'!$B:$B,Z$1) -> 0 | ... AD16: =SUMIFS('Doc''s Pagos | Rodopar 108'!$J:$J,'Doc''s Pagos | Rodopar 108'!$A:$A,$B16&$E16&$F16&$J16,'Doc''s Pagos | Rodopar 108'!$B:$B,AD$1)+SUMIFS('Doc Há Pagar | Rodopar 1015'!$J:$J,'Doc Há Pagar | Rodopar 1015'!$A:$A,$B16&$E16&$F16,'Doc Há Pagar | Rodopar 1015'!$B:$B,AD$1) -> 0
A17: =VLOOKUP($E17,Fornecedores!$A:$C,3,0) -> Frota | B17: 23645 | C17: =IFERROR(VLOOKUP($E17,Fornecedores!$A:$E,4,0),"") -> Manutenção | D17: =IFERROR(VLOOKUP($E17,Fornecedores!$A:$E,5,0),"") -> Vans | E17: MINAS MAQUINAS SA | JUIZ DE FORA | F17: NSE | G17: 21.549.423/0001-35 | H17: 87 | I17: 999 | J17: 46031 | K17: 46035 | L17: JUIZ DE FORA | M17: MG | N17: 1556 | O17: GABRIEL.ALBINO | Q17: =SUM(R17:AD17)-I17 -> 0 | S17: =SUMIFS('Doc''s Pagos | Rodopar 108'!$J:$J,'Doc''s Pagos | Rodopar 108'!$A:$A,$B17&$E17&$F17&$J17,'Doc''s Pagos | Rodopar 108'!$B:$B,S$1)+SUMIFS('Doc Há Pagar | Rodopar 1015'!$J:$J,'Doc Há Pagar | Rodopar 1015'!$A:$A,$B17&$E17&$F17,'Doc Há Pagar | Rodopar 1015'!$B:$B,S$1) -> 0 | T17: =SUMIFS('Doc''s Pagos | Rodopar 108'!$J:$J,'Doc''s Pagos | Rodopar 108'!$A:$A,$B17&$E17&$F17&$J17,'Doc''s Pagos | Rodopar 108'!$B:$B,T$1)+SUMIFS('Doc Há Pagar | Rodopar 1015'!$J:$J,'Doc Há Pagar | Rodopar 1015'!$A:$A,$B17&$E17&$F17,'Doc Há Pagar | Rodopar 1015'!$B:$B,T$1) -> 999 | U17: =SUMIFS('Doc''s Pagos | Rodopar 108'!$J:$J,'Doc''s Pagos | Rodopar 108'!$A:$A,$B17&$E17&$F17&$J17,'Doc''s Pagos | Rodopar 108'!$B:$B,U$1)+SUMIFS('Doc Há Pagar | Rodopar 1015'!$J:$J,'Doc Há Pagar | Rodopar 1015'!$A:$A,$B17&$E17&$F17,'Doc Há Pagar | Rodopar 1015'!$B:$B,U$1) -> 0 | V17: =SUMIFS('Doc''s Pagos | Rodopar 108'!$J:$J,'Doc''s Pagos | Rodopar 108'!$A:$A,$B17&$E17&$F17&$J17,'Doc''s Pagos | Rodopar 108'!$B:$B,V$1)+SUMIFS('Doc Há Pagar | Rodopar 1015'!$J:$J,'Doc Há Pagar | Rodopar 1015'!$A:$A,$B17&$E17&$F17,'Doc Há Pagar | Rodopar 1015'!$B:$B,V$1) -> 0 | W17: =SUMIFS('Doc''s Pagos | Rodopar 108'!$J:$J,'Doc''s Pagos | Rodopar 108'!$A:$A,$B17&$E17&$F17&$J17,'Doc''s Pagos | Rodopar 108'!$B:$B,W$1)+SUMIFS('Doc Há Pagar | Rodopar 1015'!$J:$J,'Doc Há Pagar | Rodopar 1015'!$A:$A,$B17&$E17&$F17,'Doc Há Pagar | Rodopar 1015'!$B:$B,W$1) -> 0 | X17: =SUMIFS('Doc''s Pagos | Rodopar 108'!$J:$J,'Doc''s Pagos | Rodopar 108'!$A:$A,$B17&$E17&$F17&$J17,'Doc''s Pagos | Rodopar 108'!$B:$B,X$1)+SUMIFS('Doc Há Pagar | Rodopar 1015'!$J:$J,'Doc Há Pagar | Rodopar 1015'!$A:$A,$B17&$E17&$F17,'Doc Há Pagar | Rodopar 1015'!$B:$B,X$1) -> 0 | Y17: =SUMIFS('Doc''s Pagos | Rodopar 108'!$J:$J,'Doc''s Pagos | Rodopar 108'!$A:$A,$B17&$E17&$F17&$J17,'Doc''s Pagos | Rodopar 108'!$B:$B,Y$1)+SUMIFS('Doc Há Pagar | Rodopar 1015'!$J:$J,'Doc Há Pagar | Rodopar 1015'!$A:$A,$B17&$E17&$F17,'Doc Há Pagar | Rodopar 1015'!$B:$B,Y$1) -> 0 | Z17: =SUMIFS('Doc''s Pagos | Rodopar 108'!$J:$J,'Doc''s Pagos | Rodopar 108'!$A:$A,$B17&$E17&$F17&$J17,'Doc''s Pagos | Rodopar 108'!$B:$B,Z$1)+SUMIFS('Doc Há Pagar | Rodopar 1015'!$J:$J,'Doc Há Pagar | Rodopar 1015'!$A:$A,$B17&$E17&$F17,'Doc Há Pagar | Rodopar 1015'!$B:$B,Z$1) -> 0 | ... AD17: =SUMIFS('Doc''s Pagos | Rodopar 108'!$J:$J,'Doc''s Pagos | Rodopar 108'!$A:$A,$B17&$E17&$F17&$J17,'Doc''s Pagos | Rodopar 108'!$B:$B,AD$1)+SUMIFS('Doc Há Pagar | Rodopar 1015'!$J:$J,'Doc Há Pagar | Rodopar 1015'!$A:$A,$B17&$E17&$F17,'Doc Há Pagar | Rodopar 1015'!$B:$B,AD$1) -> 0
A18: =VLOOKUP($E18,Fornecedores!$A:$C,3,0) -> Frota | B18: 326 | C18: =IFERROR(VLOOKUP($E18,Fornecedores!$A:$E,4,0),"") -> Lavagem | D18: =IFERROR(VLOOKUP($E18,Fornecedores!$A:$E,5,0),"") -> Lavagem | E18: LAURISNEIDE VIEIRA DA SILVA 02793491306 | F18: NSE | G18: 41.736.221/0001-00 | H18: 87 | I18: 360 | J18: 46031 | K18: 46031 | L18: UBERLANDIA | M18: MG | N18: 1556 | O18: GABRIEL.ALBINO | Q18: =SUM(R18:AD18)-I18 -> 0 | S18: =SUMIFS('Doc''s Pagos | Rodopar 108'!$J:$J,'Doc''s Pagos | Rodopar 108'!$A:$A,$B18&$E18&$F18&$J18,'Doc''s Pagos | Rodopar 108'!$B:$B,S$1)+SUMIFS('Doc Há Pagar | Rodopar 1015'!$J:$J,'Doc Há Pagar | Rodopar 1015'!$A:$A,$B18&$E18&$F18,'Doc Há Pagar | Rodopar 1015'!$B:$B,S$1) -> 0 | T18: =SUMIFS('Doc''s Pagos | Rodopar 108'!$J:$J,'Doc''s Pagos | Rodopar 108'!$A:$A,$B18&$E18&$F18&$J18,'Doc''s Pagos | Rodopar 108'!$B:$B,T$1)+SUMIFS('Doc Há Pagar | Rodopar 1015'!$J:$J,'Doc Há Pagar | Rodopar 1015'!$A:$A,$B18&$E18&$F18,'Doc Há Pagar | Rodopar 1015'!$B:$B,T$1) -> 360 | U18: =SUMIFS('Doc''s Pagos | Rodopar 108'!$J:$J,'Doc''s Pagos | Rodopar 108'!$A:$A,$B18&$E18&$F18&$J18,'Doc''s Pagos | Rodopar 108'!$B:$B,U$1)+SUMIFS('Doc Há Pagar | Rodopar 1015'!$J:$J,'Doc Há Pagar | Rodopar 1015'!$A:$A,$B18&$E18&$F18,'Doc Há Pagar | Rodopar 1015'!$B:$B,U$1) -> 0 | V18: =SUMIFS('Doc''s Pagos | Rodopar 108'!$J:$J,'Doc''s Pagos | Rodopar 108'!$A:$A,$B18&$E18&$F18&$J18,'Doc''s Pagos | Rodopar 108'!$B:$B,V$1)+SUMIFS('Doc Há Pagar | Rodopar 1015'!$J:$J,'Doc Há Pagar | Rodopar 1015'!$A:$A,$B18&$E18&$F18,'Doc Há Pagar | Rodopar 1015'!$B:$B,V$1) -> 0 | W18: =SUMIFS('Doc''s Pagos | Rodopar 108'!$J:$J,'Doc''s Pagos | Rodopar 108'!$A:$A,$B18&$E18&$F18&$J18,'Doc''s Pagos | Rodopar 108'!$B:$B,W$1)+SUMIFS('Doc Há Pagar | Rodopar 1015'!$J:$J,'Doc Há Pagar | Rodopar 1015'!$A:$A,$B18&$E18&$F18,'Doc Há Pagar | Rodopar 1015'!$B:$B,W$1) -> 0 | X18: =SUMIFS('Doc''s Pagos | Rodopar 108'!$J:$J,'Doc''s Pagos | Rodopar 108'!$A:$A,$B18&$E18&$F18&$J18,'Doc''s Pagos | Rodopar 108'!$B:$B,X$1)+SUMIFS('Doc Há Pagar | Rodopar 1015'!$J:$J,'Doc Há Pagar | Rodopar 1015'!$A:$A,$B18&$E18&$F18,'Doc Há Pagar | Rodopar 1015'!$B:$B,X$1) -> 0 | Y18: =SUMIFS('Doc''s Pagos | Rodopar 108'!$J:$J,'Doc''s Pagos | Rodopar 108'!$A:$A,$B18&$E18&$F18&$J18,'Doc''s Pagos | Rodopar 108'!$B:$B,Y$1)+SUMIFS('Doc Há Pagar | Rodopar 1015'!$J:$J,'Doc Há Pagar | Rodopar 1015'!$A:$A,$B18&$E18&$F18,'Doc Há Pagar | Rodopar 1015'!$B:$B,Y$1) -> 0 | Z18: =SUMIFS('Doc''s Pagos | Rodopar 108'!$J:$J,'Doc''s Pagos | Rodopar 108'!$A:$A,$B18&$E18&$F18&$J18,'Doc''s Pagos | Rodopar 108'!$B:$B,Z$1)+SUMIFS('Doc Há Pagar | Rodopar 1015'!$J:$J,'Doc Há Pagar | Rodopar 1015'!$A:$A,$B18&$E18&$F18,'Doc Há Pagar | Rodopar 1015'!$B:$B,Z$1) -> 0 | ... AD18: =SUMIFS('Doc''s Pagos | Rodopar 108'!$J:$J,'Doc''s Pagos | Rodopar 108'!$A:$A,$B18&$E18&$F18&$J18,'Doc''s Pagos | Rodopar 108'!$B:$B,AD$1)+SUMIFS('Doc Há Pagar | Rodopar 1015'!$J:$J,'Doc Há Pagar | Rodopar 1015'!$A:$A,$B18&$E18&$F18,'Doc Há Pagar | Rodopar 1015'!$B:$B,AD$1) -> 0
A19: =VLOOKUP($E19,Fornecedores!$A:$C,3,0) -> Frota | B19: 6 | C19: =IFERROR(VLOOKUP($E19,Fornecedores!$A:$E,4,0),"") -> Lavagem | D19: =IFERROR(VLOOKUP($E19,Fornecedores!$A:$E,5,0),"") -> Lavagem | E19: HIGOR RODNEY CIMINI DA COSTA | F19: NSE | G19: 29.524.404/0001-66 | H19: 87 | I19: 12450 | J19: 46031 | K19: 46034 | L19: CONTAGEM | M19: MG | N19: 1556 | O19: GABRIEL.ALBINO | Q19: =SUM(R19:AD19)-I19 -> 0 | S19: =SUMIFS('Doc''s Pagos | Rodopar 108'!$J:$J,'Doc''s Pagos | Rodopar 108'!$A:$A,$B19&$E19&$F19&$J19,'Doc''s Pagos | Rodopar 108'!$B:$B,S$1)+SUMIFS('Doc Há Pagar | Rodopar 1015'!$J:$J,'Doc Há Pagar | Rodopar 1015'!$A:$A,$B19&$E19&$F19,'Doc Há Pagar | Rodopar 1015'!$B:$B,S$1) -> 0 | T19: =SUMIFS('Doc''s Pagos | Rodopar 108'!$J:$J,'Doc''s Pagos | Rodopar 108'!$A:$A,$B19&$E19&$F19&$J19,'Doc''s Pagos | Rodopar 108'!$B:$B,T$1)+SUMIFS('Doc Há Pagar | Rodopar 1015'!$J:$J,'Doc Há Pagar | Rodopar 1015'!$A:$A,$B19&$E19&$F19,'Doc Há Pagar | Rodopar 1015'!$B:$B,T$1) -> 12450 | U19: =SUMIFS('Doc''s Pagos | Rodopar 108'!$J:$J,'Doc''s Pagos | Rodopar 108'!$A:$A,$B19&$E19&$F19&$J19,'Doc''s Pagos | Rodopar 108'!$B:$B,U$1)+SUMIFS('Doc Há Pagar | Rodopar 1015'!$J:$J,'Doc Há Pagar | Rodopar 1015'!$A:$A,$B19&$E19&$F19,'Doc Há Pagar | Rodopar 1015'!$B:$B,U$1) -> 0 | V19: =SUMIFS('Doc''s Pagos | Rodopar 108'!$J:$J,'Doc''s Pagos | Rodopar 108'!$A:$A,$B19&$E19&$F19&$J19,'Doc''s Pagos | Rodopar 108'!$B:$B,V$1)+SUMIFS('Doc Há Pagar | Rodopar 1015'!$J:$J,'Doc Há Pagar | Rodopar 1015'!$A:$A,$B19&$E19&$F19,'Doc Há Pagar | Rodopar 1015'!$B:$B,V$1) -> 0 | W19: =SUMIFS('Doc''s Pagos | Rodopar 108'!$J:$J,'Doc''s Pagos | Rodopar 108'!$A:$A,$B19&$E19&$F19&$J19,'Doc''s Pagos | Rodopar 108'!$B:$B,W$1)+SUMIFS('Doc Há Pagar | Rodopar 1015'!$J:$J,'Doc Há Pagar | Rodopar 1015'!$A:$A,$B19&$E19&$F19,'Doc Há Pagar | Rodopar 1015'!$B:$B,W$1) -> 0 | X19: =SUMIFS('Doc''s Pagos | Rodopar 108'!$J:$J,'Doc''s Pagos | Rodopar 108'!$A:$A,$B19&$E19&$F19&$J19,'Doc''s Pagos | Rodopar 108'!$B:$B,X$1)+SUMIFS('Doc Há Pagar | Rodopar 1015'!$J:$J,'Doc Há Pagar | Rodopar 1015'!$A:$A,$B19&$E19&$F19,'Doc Há Pagar | Rodopar 1015'!$B:$B,X$1) -> 0 | Y19: =SUMIFS('Doc''s Pagos | Rodopar 108'!$J:$J,'Doc''s Pagos | Rodopar 108'!$A:$A,$B19&$E19&$F19&$J19,'Doc''s Pagos | Rodopar 108'!$B:$B,Y$1)+SUMIFS('Doc Há Pagar | Rodopar 1015'!$J:$J,'Doc Há Pagar | Rodopar 1015'!$A:$A,$B19&$E19&$F19,'Doc Há Pagar | Rodopar 1015'!$B:$B,Y$1) -> 0 | Z19: =SUMIFS('Doc''s Pagos | Rodopar 108'!$J:$J,'Doc''s Pagos | Rodopar 108'!$A:$A,$B19&$E19&$F19&$J19,'Doc''s Pagos | Rodopar 108'!$B:$B,Z$1)+SUMIFS('Doc Há Pagar | Rodopar 1015'!$J:$J,'Doc Há Pagar | Rodopar 1015'!$A:$A,$B19&$E19&$F19,'Doc Há Pagar | Rodopar 1015'!$B:$B,Z$1) -> 0 | ... AD19: =SUMIFS('Doc''s Pagos | Rodopar 108'!$J:$J,'Doc''s Pagos | Rodopar 108'!$A:$A,$B19&$E19&$F19&$J19,'Doc''s Pagos | Rodopar 108'!$B:$B,AD$1)+SUMIFS('Doc Há Pagar | Rodopar 1015'!$J:$J,'Doc Há Pagar | Rodopar 1015'!$A:$A,$B19&$E19&$F19,'Doc Há Pagar | Rodopar 1015'!$B:$B,AD$1) -> 0
A20: =VLOOKUP($E20,Fornecedores!$A:$C,3,0) -> Frota | B20: 222247 | C20: =IFERROR(VLOOKUP($E20,Fornecedores!$A:$E,4,0),"") -> Manutenção | D20: =IFERROR(VLOOKUP($E20,Fornecedores!$A:$E,5,0),"") -> Peças E Serviços | E20: A C FARIAS COM. DE PEÇAS E SERVIÇOS. EIRELI EPP | F20: NFE | G20: 11.384.025/0001-52 | H20: 87 | I20: 1458 | J20: 46034 | K20: 46034 | L20: ANANINDEUA | M20: PA | N20: 2556 | O20: GABRIEL.ALBINO | Q20: =SUM(R20:AD20)-I20 -> 0 | S20: =SUMIFS('Doc''s Pagos | Rodopar 108'!$J:$J,'Doc''s Pagos | Rodopar 108'!$A:$A,$B20&$E20&$F20&$J20,'Doc''s Pagos | Rodopar 108'!$B:$B,S$1)+SUMIFS('Doc Há Pagar | Rodopar 1015'!$J:$J,'Doc Há Pagar | Rodopar 1015'!$A:$A,$B20&$E20&$F20,'Doc Há Pagar | Rodopar 1015'!$B:$B,S$1) -> 0 | T20: =SUMIFS('Doc''s Pagos | Rodopar 108'!$J:$J,'Doc''s Pagos | Rodopar 108'!$A:$A,$B20&$E20&$F20&$J20,'Doc''s Pagos | Rodopar 108'!$B:$B,T$1)+SUMIFS('Doc Há Pagar | Rodopar 1015'!$J:$J,'Doc Há Pagar | Rodopar 1015'!$A:$A,$B20&$E20&$F20,'Doc Há Pagar | Rodopar 1015'!$B:$B,T$1) -> 1458 | U20: =SUMIFS('Doc''s Pagos | Rodopar 108'!$J:$J,'Doc''s Pagos | Rodopar 108'!$A:$A,$B20&$E20&$F20&$J20,'Doc''s Pagos | Rodopar 108'!$B:$B,U$1)+SUMIFS('Doc Há Pagar | Rodopar 1015'!$J:$J,'Doc Há Pagar | Rodopar 1015'!$A:$A,$B20&$E20&$F20,'Doc Há Pagar | Rodopar 1015'!$B:$B,U$1) -> 0 | V20: =SUMIFS('Doc''s Pagos | Rodopar 108'!$J:$J,'Doc''s Pagos | Rodopar 108'!$A:$A,$B20&$E20&$F20&$J20,'Doc''s Pagos | Rodopar 108'!$B:$B,V$1)+SUMIFS('Doc Há Pagar | Rodopar 1015'!$J:$J,'Doc Há Pagar | Rodopar 1015'!$A:$A,$B20&$E20&$F20,'Doc Há Pagar | Rodopar 1015'!$B:$B,V$1) -> 0 | W20: =SUMIFS('Doc''s Pagos | Rodopar 108'!$J:$J,'Doc''s Pagos | Rodopar 108'!$A:$A,$B20&$E20&$F20&$J20,'Doc''s Pagos | Rodopar 108'!$B:$B,W$1)+SUMIFS('Doc Há Pagar | Rodopar 1015'!$J:$J,'Doc Há Pagar | Rodopar 1015'!$A:$A,$B20&$E20&$F20,'Doc Há Pagar | Rodopar 1015'!$B:$B,W$1) -> 0 | X20: =SUMIFS('Doc''s Pagos | Rodopar 108'!$J:$J,'Doc''s Pagos | Rodopar 108'!$A:$A,$B20&$E20&$F20&$J20,'Doc''s Pagos | Rodopar 108'!$B:$B,X$1)+SUMIFS('Doc Há Pagar | Rodopar 1015'!$J:$J,'Doc Há Pagar | Rodopar 1015'!$A:$A,$B20&$E20&$F20,'Doc Há Pagar | Rodopar 1015'!$B:$B,X$1) -> 0 | Y20: =SUMIFS('Doc''s Pagos | Rodopar 108'!$J:$J,'Doc''s Pagos | Rodopar 108'!$A:$A,$B20&$E20&$F20&$J20,'Doc''s Pagos | Rodopar 108'!$B:$B,Y$1)+SUMIFS('Doc Há Pagar | Rodopar 1015'!$J:$J,'Doc Há Pagar | Rodopar 1015'!$A:$A,$B20&$E20&$F20,'Doc Há Pagar | Rodopar 1015'!$B:$B,Y$1) -> 0 | Z20: =SUMIFS('Doc''s Pagos | Rodopar 108'!$J:$J,'Doc''s Pagos | Rodopar 108'!$A:$A,$B20&$E20&$F20&$J20,'Doc''s Pagos | Rodopar 108'!$B:$B,Z$1)+SUMIFS('Doc Há Pagar | Rodopar 1015'!$J:$J,'Doc Há Pagar | Rodopar 1015'!$A:$A,$B20&$E20&$F20,'Doc Há Pagar | Rodopar 1015'!$B:$B,Z$1) -> 0 | ... AD20: =SUMIFS('Doc''s Pagos | Rodopar 108'!$J:$J,'Doc''s Pagos | Rodopar 108'!$A:$A,$B20&$E20&$F20&$J20,'Doc''s Pagos | Rodopar 108'!$B:$B,AD$1)+SUMIFS('Doc Há Pagar | Rodopar 1015'!$J:$J,'Doc Há Pagar | Rodopar 1015'!$A:$A,$B20&$E20&$F20,'Doc Há Pagar | Rodopar 1015'!$B:$B,AD$1) -> 0
A21: =VLOOKUP($E21,Fornecedores!$A:$C,3,0) -> Frota | B21: 90 | C21: =IFERROR(VLOOKUP($E21,Fornecedores!$A:$E,4,0),"") -> Manutenção | D21: =IFERROR(VLOOKUP($E21,Fornecedores!$A:$E,5,0),"") -> Peças E Serviços | E21: ZAMBALDI AUTO CENTER LTDA | F21: NFE | G21: 55.012.105/0001-52 | H21: 87 | I21: 594.98 | J21: 46035 | K21: 46036 | L21: CONTAGEM | M21: MG | N21: 1556 | O21: GABRIEL.ALBINO | Q21: =SUM(R21:AD21)-I21 -> 0 | S21: =SUMIFS('Doc''s Pagos | Rodopar 108'!$J:$J,'Doc''s Pagos | Rodopar 108'!$A:$A,$B21&$E21&$F21&$J21,'Doc''s Pagos | Rodopar 108'!$B:$B,S$1)+SUMIFS('Doc Há Pagar | Rodopar 1015'!$J:$J,'Doc Há Pagar | Rodopar 1015'!$A:$A,$B21&$E21&$F21,'Doc Há Pagar | Rodopar 1015'!$B:$B,S$1) -> 0 | T21: =SUMIFS('Doc''s Pagos | Rodopar 108'!$J:$J,'Doc''s Pagos | Rodopar 108'!$A:$A,$B21&$E21&$F21&$J21,'Doc''s Pagos | Rodopar 108'!$B:$B,T$1)+SUMIFS('Doc Há Pagar | Rodopar 1015'!$J:$J,'Doc Há Pagar | Rodopar 1015'!$A:$A,$B21&$E21&$F21,'Doc Há Pagar | Rodopar 1015'!$B:$B,T$1) -> 594.98 | U21: =SUMIFS('Doc''s Pagos | Rodopar 108'!$J:$J,'Doc''s Pagos | Rodopar 108'!$A:$A,$B21&$E21&$F21&$J21,'Doc''s Pagos | Rodopar 108'!$B:$B,U$1)+SUMIFS('Doc Há Pagar | Rodopar 1015'!$J:$J,'Doc Há Pagar | Rodopar 1015'!$A:$A,$B21&$E21&$F21,'Doc Há Pagar | Rodopar 1015'!$B:$B,U$1) -> 0 | V21: =SUMIFS('Doc''s Pagos | Rodopar 108'!$J:$J,'Doc''s Pagos | Rodopar 108'!$A:$A,$B21&$E21&$F21&$J21,'Doc''s Pagos | Rodopar 108'!$B:$B,V$1)+SUMIFS('Doc Há Pagar | Rodopar 1015'!$J:$J,'Doc Há Pagar | Rodopar 1015'!$A:$A,$B21&$E21&$F21,'Doc Há Pagar | Rodopar 1015'!$B:$B,V$1) -> 0 | W21: =SUMIFS('Doc''s Pagos | Rodopar 108'!$J:$J,'Doc''s Pagos | Rodopar 108'!$A:$A,$B21&$E21&$F21&$J21,'Doc''s Pagos | Rodopar 108'!$B:$B,W$1)+SUMIFS('Doc Há Pagar | Rodopar 1015'!$J:$J,'Doc Há Pagar | Rodopar 1015'!$A:$A,$B21&$E21&$F21,'Doc Há Pagar | Rodopar 1015'!$B:$B,W$1) -> 0 | X21: =SUMIFS('Doc''s Pagos | Rodopar 108'!$J:$J,'Doc''s Pagos | Rodopar 108'!$A:$A,$B21&$E21&$F21&$J21,'Doc''s Pagos | Rodopar 108'!$B:$B,X$1)+SUMIFS('Doc Há Pagar | Rodopar 1015'!$J:$J,'Doc Há Pagar | Rodopar 1015'!$A:$A,$B21&$E21&$F21,'Doc Há Pagar | Rodopar 1015'!$B:$B,X$1) -> 0 | Y21: =SUMIFS('Doc''s Pagos | Rodopar 108'!$J:$J,'Doc''s Pagos | Rodopar 108'!$A:$A,$B21&$E21&$F21&$J21,'Doc''s Pagos | Rodopar 108'!$B:$B,Y$1)+SUMIFS('Doc Há Pagar | Rodopar 1015'!$J:$J,'Doc Há Pagar | Rodopar 1015'!$A:$A,$B21&$E21&$F21,'Doc Há Pagar | Rodopar 1015'!$B:$B,Y$1) -> 0 | Z21: =SUMIFS('Doc''s Pagos | Rodopar 108'!$J:$J,'Doc''s Pagos | Rodopar 108'!$A:$A,$B21&$E21&$F21&$J21,'Doc''s Pagos | Rodopar 108'!$B:$B,Z$1)+SUMIFS('Doc Há Pagar | Rodopar 1015'!$J:$J,'Doc Há Pagar | Rodopar 1015'!$A:$A,$B21&$E21&$F21,'Doc Há Pagar | Rodopar 1015'!$B:$B,Z$1) -> 0 | ... AD21: =SUMIFS('Doc''s Pagos | Rodopar 108'!$J:$J,'Doc''s Pagos | Rodopar 108'!$A:$A,$B21&$E21&$F21&$J21,'Doc''s Pagos | Rodopar 108'!$B:$B,AD$1)+SUMIFS('Doc Há Pagar | Rodopar 1015'!$J:$J,'Doc Há Pagar | Rodopar 1015'!$A:$A,$B21&$E21&$F21,'Doc Há Pagar | Rodopar 1015'!$B:$B,AD$1) -> 0
